Internal Server Error: /account/upload_image/
Traceback (most recent call last):
  File "/Users/jairajsahgal/.local/share/virtualenvs/text_recognition-eMREPB2y/lib/python3.9/site-packages/django/core/handlers/exception.py", line 55, in inner
    response = get_response(request)
  File "/Users/jairajsahgal/.local/share/virtualenvs/text_recognition-eMREPB2y/lib/python3.9/site-packages/django/core/handlers/base.py", line 197, in _get_response
    response = wrapped_callback(request, *callback_args, **callback_kwargs)
  File "/Users/jairajsahgal/.local/share/virtualenvs/text_recognition-eMREPB2y/lib/python3.9/site-packages/django/views/decorators/csrf.py", line 54, in wrapped_view
    return view_func(*args, **kwargs)
  File "/Users/jairajsahgal/.local/share/virtualenvs/text_recognition-eMREPB2y/lib/python3.9/site-packages/django/views/generic/base.py", line 84, in view
    return self.dispatch(request, *args, **kwargs)
  File "/Users/jairajsahgal/.local/share/virtualenvs/text_recognition-eMREPB2y/lib/python3.9/site-packages/rest_framework/views.py", line 492, in dispatch
    request = self.initialize_request(request, *args, **kwargs)
  File "/Users/jairajsahgal/.local/share/virtualenvs/text_recognition-eMREPB2y/lib/python3.9/site-packages/rest_framework/views.py", line 393, in initialize_request
    parsers=self.get_parsers(),
  File "/Users/jairajsahgal/.local/share/virtualenvs/text_recognition-eMREPB2y/lib/python3.9/site-packages/rest_framework/views.py", line 266, in get_parsers
    return [parser() for parser in self.parser_classes]
  File "/Users/jairajsahgal/.local/share/virtualenvs/text_recognition-eMREPB2y/lib/python3.9/site-packages/rest_framework/views.py", line 266, in <listcomp>
    return [parser() for parser in self.parser_classes]
TypeError: 'str' object is not callable
Internal Server Error: /account/upload_image/
Traceback (most recent call last):
  File "/Users/jairajsahgal/.local/share/virtualenvs/text_recognition-eMREPB2y/lib/python3.9/site-packages/django/core/handlers/exception.py", line 55, in inner
    response = get_response(request)
  File "/Users/jairajsahgal/.local/share/virtualenvs/text_recognition-eMREPB2y/lib/python3.9/site-packages/django/core/handlers/base.py", line 197, in _get_response
    response = wrapped_callback(request, *callback_args, **callback_kwargs)
  File "/Users/jairajsahgal/.local/share/virtualenvs/text_recognition-eMREPB2y/lib/python3.9/site-packages/django/views/decorators/csrf.py", line 54, in wrapped_view
    return view_func(*args, **kwargs)
  File "/Users/jairajsahgal/.local/share/virtualenvs/text_recognition-eMREPB2y/lib/python3.9/site-packages/django/views/generic/base.py", line 84, in view
    return self.dispatch(request, *args, **kwargs)
  File "/Users/jairajsahgal/.local/share/virtualenvs/text_recognition-eMREPB2y/lib/python3.9/site-packages/rest_framework/views.py", line 492, in dispatch
    request = self.initialize_request(request, *args, **kwargs)
  File "/Users/jairajsahgal/.local/share/virtualenvs/text_recognition-eMREPB2y/lib/python3.9/site-packages/rest_framework/views.py", line 393, in initialize_request
    parsers=self.get_parsers(),
  File "/Users/jairajsahgal/.local/share/virtualenvs/text_recognition-eMREPB2y/lib/python3.9/site-packages/rest_framework/views.py", line 266, in get_parsers
    return [parser() for parser in self.parser_classes]
  File "/Users/jairajsahgal/.local/share/virtualenvs/text_recognition-eMREPB2y/lib/python3.9/site-packages/rest_framework/views.py", line 266, in <listcomp>
    return [parser() for parser in self.parser_classes]
TypeError: 'str' object is not callable
Internal Server Error: /account/upload_image/
Traceback (most recent call last):
  File "/Users/jairajsahgal/.local/share/virtualenvs/text_recognition-eMREPB2y/lib/python3.9/site-packages/django/core/handlers/exception.py", line 55, in inner
    response = get_response(request)
  File "/Users/jairajsahgal/.local/share/virtualenvs/text_recognition-eMREPB2y/lib/python3.9/site-packages/django/core/handlers/base.py", line 197, in _get_response
    response = wrapped_callback(request, *callback_args, **callback_kwargs)
  File "/Users/jairajsahgal/.local/share/virtualenvs/text_recognition-eMREPB2y/lib/python3.9/site-packages/django/views/decorators/csrf.py", line 54, in wrapped_view
    return view_func(*args, **kwargs)
  File "/Users/jairajsahgal/.local/share/virtualenvs/text_recognition-eMREPB2y/lib/python3.9/site-packages/django/views/generic/base.py", line 84, in view
    return self.dispatch(request, *args, **kwargs)
  File "/Users/jairajsahgal/.local/share/virtualenvs/text_recognition-eMREPB2y/lib/python3.9/site-packages/rest_framework/views.py", line 492, in dispatch
    request = self.initialize_request(request, *args, **kwargs)
  File "/Users/jairajsahgal/.local/share/virtualenvs/text_recognition-eMREPB2y/lib/python3.9/site-packages/rest_framework/views.py", line 393, in initialize_request
    parsers=self.get_parsers(),
  File "/Users/jairajsahgal/.local/share/virtualenvs/text_recognition-eMREPB2y/lib/python3.9/site-packages/rest_framework/views.py", line 266, in get_parsers
    return [parser() for parser in self.parser_classes]
  File "/Users/jairajsahgal/.local/share/virtualenvs/text_recognition-eMREPB2y/lib/python3.9/site-packages/rest_framework/views.py", line 266, in <listcomp>
    return [parser() for parser in self.parser_classes]
TypeError: 'str' object is not callable
Internal Server Error: /account/upload_image/
Traceback (most recent call last):
  File "/Users/jairajsahgal/.local/share/virtualenvs/text_recognition-eMREPB2y/lib/python3.9/site-packages/django/core/handlers/exception.py", line 55, in inner
    response = get_response(request)
  File "/Users/jairajsahgal/.local/share/virtualenvs/text_recognition-eMREPB2y/lib/python3.9/site-packages/django/core/handlers/base.py", line 197, in _get_response
    response = wrapped_callback(request, *callback_args, **callback_kwargs)
  File "/Users/jairajsahgal/.local/share/virtualenvs/text_recognition-eMREPB2y/lib/python3.9/site-packages/django/views/decorators/csrf.py", line 54, in wrapped_view
    return view_func(*args, **kwargs)
  File "/Users/jairajsahgal/.local/share/virtualenvs/text_recognition-eMREPB2y/lib/python3.9/site-packages/django/views/generic/base.py", line 84, in view
    return self.dispatch(request, *args, **kwargs)
  File "/Users/jairajsahgal/.local/share/virtualenvs/text_recognition-eMREPB2y/lib/python3.9/site-packages/rest_framework/views.py", line 492, in dispatch
    request = self.initialize_request(request, *args, **kwargs)
  File "/Users/jairajsahgal/.local/share/virtualenvs/text_recognition-eMREPB2y/lib/python3.9/site-packages/rest_framework/views.py", line 393, in initialize_request
    parsers=self.get_parsers(),
  File "/Users/jairajsahgal/.local/share/virtualenvs/text_recognition-eMREPB2y/lib/python3.9/site-packages/rest_framework/views.py", line 266, in get_parsers
    return [parser() for parser in self.parser_classes]
  File "/Users/jairajsahgal/.local/share/virtualenvs/text_recognition-eMREPB2y/lib/python3.9/site-packages/rest_framework/views.py", line 266, in <listcomp>
    return [parser() for parser in self.parser_classes]
TypeError: 'str' object is not callable
Internal Server Error: /account/upload_image/
Traceback (most recent call last):
  File "/Users/jairajsahgal/.local/share/virtualenvs/text_recognition-eMREPB2y/lib/python3.9/site-packages/django/core/handlers/exception.py", line 55, in inner
    response = get_response(request)
  File "/Users/jairajsahgal/.local/share/virtualenvs/text_recognition-eMREPB2y/lib/python3.9/site-packages/django/core/handlers/base.py", line 197, in _get_response
    response = wrapped_callback(request, *callback_args, **callback_kwargs)
  File "/Users/jairajsahgal/.local/share/virtualenvs/text_recognition-eMREPB2y/lib/python3.9/site-packages/django/views/decorators/csrf.py", line 54, in wrapped_view
    return view_func(*args, **kwargs)
  File "/Users/jairajsahgal/.local/share/virtualenvs/text_recognition-eMREPB2y/lib/python3.9/site-packages/django/views/generic/base.py", line 84, in view
    return self.dispatch(request, *args, **kwargs)
  File "/Users/jairajsahgal/.local/share/virtualenvs/text_recognition-eMREPB2y/lib/python3.9/site-packages/rest_framework/views.py", line 492, in dispatch
    request = self.initialize_request(request, *args, **kwargs)
  File "/Users/jairajsahgal/.local/share/virtualenvs/text_recognition-eMREPB2y/lib/python3.9/site-packages/rest_framework/views.py", line 393, in initialize_request
    parsers=self.get_parsers(),
  File "/Users/jairajsahgal/.local/share/virtualenvs/text_recognition-eMREPB2y/lib/python3.9/site-packages/rest_framework/views.py", line 266, in get_parsers
    return [parser() for parser in self.parser_classes]
  File "/Users/jairajsahgal/.local/share/virtualenvs/text_recognition-eMREPB2y/lib/python3.9/site-packages/rest_framework/views.py", line 266, in <listcomp>
    return [parser() for parser in self.parser_classes]
TypeError: 'str' object is not callable
Internal Server Error: /account/upload_image/
Traceback (most recent call last):
  File "/Users/jairajsahgal/.local/share/virtualenvs/text_recognition-eMREPB2y/lib/python3.9/site-packages/django/core/handlers/exception.py", line 55, in inner
    response = get_response(request)
  File "/Users/jairajsahgal/.local/share/virtualenvs/text_recognition-eMREPB2y/lib/python3.9/site-packages/django/core/handlers/base.py", line 197, in _get_response
    response = wrapped_callback(request, *callback_args, **callback_kwargs)
  File "/Users/jairajsahgal/.local/share/virtualenvs/text_recognition-eMREPB2y/lib/python3.9/site-packages/django/views/decorators/csrf.py", line 54, in wrapped_view
    return view_func(*args, **kwargs)
  File "/Users/jairajsahgal/.local/share/virtualenvs/text_recognition-eMREPB2y/lib/python3.9/site-packages/django/views/generic/base.py", line 84, in view
    return self.dispatch(request, *args, **kwargs)
  File "/Users/jairajsahgal/.local/share/virtualenvs/text_recognition-eMREPB2y/lib/python3.9/site-packages/rest_framework/views.py", line 509, in dispatch
    response = self.handle_exception(exc)
  File "/Users/jairajsahgal/.local/share/virtualenvs/text_recognition-eMREPB2y/lib/python3.9/site-packages/rest_framework/views.py", line 469, in handle_exception
    self.raise_uncaught_exception(exc)
  File "/Users/jairajsahgal/.local/share/virtualenvs/text_recognition-eMREPB2y/lib/python3.9/site-packages/rest_framework/views.py", line 480, in raise_uncaught_exception
    raise exc
  File "/Users/jairajsahgal/.local/share/virtualenvs/text_recognition-eMREPB2y/lib/python3.9/site-packages/rest_framework/views.py", line 506, in dispatch
    response = handler(request, *args, **kwargs)
  File "/Users/jairajsahgal/.local/share/virtualenvs/text_recognition-eMREPB2y/lib/python3.9/site-packages/rest_framework/decorators.py", line 50, in handler
    return func(*args, **kwargs)
  File "/Users/jairajsahgal/Documents/django/text_recognition_api/text_recognition/api/views.py", line 74, in uploadImage
    print(serializer.data)
  File "/Users/jairajsahgal/.local/share/virtualenvs/text_recognition-eMREPB2y/lib/python3.9/site-packages/rest_framework/serializers.py", line 555, in data
    ret = super().data
  File "/Users/jairajsahgal/.local/share/virtualenvs/text_recognition-eMREPB2y/lib/python3.9/site-packages/rest_framework/serializers.py", line 249, in data
    raise AssertionError(msg)
AssertionError: When a serializer is passed a `data` keyword argument you must call `.is_valid()` before attempting to access the serialized `.data` representation.
You should either call `.is_valid()` first, or access `.initial_data` instead.
Internal Server Error: /account/upload_image/
Traceback (most recent call last):
  File "/Users/jairajsahgal/.local/share/virtualenvs/text_recognition-eMREPB2y/lib/python3.9/site-packages/django/core/handlers/exception.py", line 55, in inner
    response = get_response(request)
  File "/Users/jairajsahgal/.local/share/virtualenvs/text_recognition-eMREPB2y/lib/python3.9/site-packages/django/core/handlers/base.py", line 197, in _get_response
    response = wrapped_callback(request, *callback_args, **callback_kwargs)
  File "/Users/jairajsahgal/.local/share/virtualenvs/text_recognition-eMREPB2y/lib/python3.9/site-packages/django/views/decorators/csrf.py", line 54, in wrapped_view
    return view_func(*args, **kwargs)
  File "/Users/jairajsahgal/.local/share/virtualenvs/text_recognition-eMREPB2y/lib/python3.9/site-packages/django/views/generic/base.py", line 84, in view
    return self.dispatch(request, *args, **kwargs)
  File "/Users/jairajsahgal/.local/share/virtualenvs/text_recognition-eMREPB2y/lib/python3.9/site-packages/rest_framework/views.py", line 509, in dispatch
    response = self.handle_exception(exc)
  File "/Users/jairajsahgal/.local/share/virtualenvs/text_recognition-eMREPB2y/lib/python3.9/site-packages/rest_framework/views.py", line 469, in handle_exception
    self.raise_uncaught_exception(exc)
  File "/Users/jairajsahgal/.local/share/virtualenvs/text_recognition-eMREPB2y/lib/python3.9/site-packages/rest_framework/views.py", line 480, in raise_uncaught_exception
    raise exc
  File "/Users/jairajsahgal/.local/share/virtualenvs/text_recognition-eMREPB2y/lib/python3.9/site-packages/rest_framework/views.py", line 506, in dispatch
    response = handler(request, *args, **kwargs)
  File "/Users/jairajsahgal/.local/share/virtualenvs/text_recognition-eMREPB2y/lib/python3.9/site-packages/rest_framework/decorators.py", line 50, in handler
    return func(*args, **kwargs)
  File "/Users/jairajsahgal/Documents/django/text_recognition_api/text_recognition/api/views.py", line 76, in uploadImage
    serializer.save()
  File "/Users/jairajsahgal/.local/share/virtualenvs/text_recognition-eMREPB2y/lib/python3.9/site-packages/rest_framework/serializers.py", line 212, in save
    self.instance = self.create(validated_data)
  File "/Users/jairajsahgal/.local/share/virtualenvs/text_recognition-eMREPB2y/lib/python3.9/site-packages/rest_framework/serializers.py", line 962, in create
    instance = ModelClass._default_manager.create(**validated_data)
  File "/Users/jairajsahgal/.local/share/virtualenvs/text_recognition-eMREPB2y/lib/python3.9/site-packages/django/db/models/manager.py", line 85, in manager_method
    return getattr(self.get_queryset(), name)(*args, **kwargs)
  File "/Users/jairajsahgal/.local/share/virtualenvs/text_recognition-eMREPB2y/lib/python3.9/site-packages/django/db/models/query.py", line 514, in create
    obj.save(force_insert=True, using=self.db)
  File "/Users/jairajsahgal/.local/share/virtualenvs/text_recognition-eMREPB2y/lib/python3.9/site-packages/django/db/models/base.py", line 806, in save
    self.save_base(
  File "/Users/jairajsahgal/.local/share/virtualenvs/text_recognition-eMREPB2y/lib/python3.9/site-packages/django/db/models/base.py", line 857, in save_base
    updated = self._save_table(
  File "/Users/jairajsahgal/.local/share/virtualenvs/text_recognition-eMREPB2y/lib/python3.9/site-packages/django/db/models/base.py", line 1000, in _save_table
    results = self._do_insert(
  File "/Users/jairajsahgal/.local/share/virtualenvs/text_recognition-eMREPB2y/lib/python3.9/site-packages/django/db/models/base.py", line 1041, in _do_insert
    return manager._insert(
  File "/Users/jairajsahgal/.local/share/virtualenvs/text_recognition-eMREPB2y/lib/python3.9/site-packages/django/db/models/manager.py", line 85, in manager_method
    return getattr(self.get_queryset(), name)(*args, **kwargs)
  File "/Users/jairajsahgal/.local/share/virtualenvs/text_recognition-eMREPB2y/lib/python3.9/site-packages/django/db/models/query.py", line 1434, in _insert
    return query.get_compiler(using=using).execute_sql(returning_fields)
  File "/Users/jairajsahgal/.local/share/virtualenvs/text_recognition-eMREPB2y/lib/python3.9/site-packages/django/db/models/sql/compiler.py", line 1620, in execute_sql
    for sql, params in self.as_sql():
  File "/Users/jairajsahgal/.local/share/virtualenvs/text_recognition-eMREPB2y/lib/python3.9/site-packages/django/db/models/sql/compiler.py", line 1547, in as_sql
    value_rows = [
  File "/Users/jairajsahgal/.local/share/virtualenvs/text_recognition-eMREPB2y/lib/python3.9/site-packages/django/db/models/sql/compiler.py", line 1548, in <listcomp>
    [
  File "/Users/jairajsahgal/.local/share/virtualenvs/text_recognition-eMREPB2y/lib/python3.9/site-packages/django/db/models/sql/compiler.py", line 1549, in <listcomp>
    self.prepare_value(field, self.pre_save_val(field, obj))
  File "/Users/jairajsahgal/.local/share/virtualenvs/text_recognition-eMREPB2y/lib/python3.9/site-packages/django/db/models/sql/compiler.py", line 1497, in pre_save_val
    return field.pre_save(obj, add=True)
  File "/Users/jairajsahgal/.local/share/virtualenvs/text_recognition-eMREPB2y/lib/python3.9/site-packages/django/db/models/fields/files.py", line 316, in pre_save
    file.save(file.name, file.file, save=False)
  File "/Users/jairajsahgal/.local/share/virtualenvs/text_recognition-eMREPB2y/lib/python3.9/site-packages/django/db/models/fields/files.py", line 91, in save
    name = self.field.generate_filename(self.instance, name)
  File "/Users/jairajsahgal/.local/share/virtualenvs/text_recognition-eMREPB2y/lib/python3.9/site-packages/django/db/models/fields/files.py", line 331, in generate_filename
    filename = self.upload_to(instance, filename)
  File "/Users/jairajsahgal/Documents/django/text_recognition_api/text_recognition/api/models.py", line 6, in nameFile
    return '/'.join(['images', str(instance.name), filename])
AttributeError: 'Picture' object has no attribute 'name'
Internal Server Error: /account/upload_image/
Traceback (most recent call last):
  File "/Users/jairajsahgal/.local/share/virtualenvs/text_recognition-eMREPB2y/lib/python3.9/site-packages/django/core/handlers/exception.py", line 55, in inner
    response = get_response(request)
  File "/Users/jairajsahgal/.local/share/virtualenvs/text_recognition-eMREPB2y/lib/python3.9/site-packages/django/core/handlers/base.py", line 197, in _get_response
    response = wrapped_callback(request, *callback_args, **callback_kwargs)
  File "/Users/jairajsahgal/.local/share/virtualenvs/text_recognition-eMREPB2y/lib/python3.9/site-packages/django/views/decorators/csrf.py", line 54, in wrapped_view
    return view_func(*args, **kwargs)
  File "/Users/jairajsahgal/.local/share/virtualenvs/text_recognition-eMREPB2y/lib/python3.9/site-packages/django/views/generic/base.py", line 84, in view
    return self.dispatch(request, *args, **kwargs)
  File "/Users/jairajsahgal/.local/share/virtualenvs/text_recognition-eMREPB2y/lib/python3.9/site-packages/rest_framework/views.py", line 509, in dispatch
    response = self.handle_exception(exc)
  File "/Users/jairajsahgal/.local/share/virtualenvs/text_recognition-eMREPB2y/lib/python3.9/site-packages/rest_framework/views.py", line 469, in handle_exception
    self.raise_uncaught_exception(exc)
  File "/Users/jairajsahgal/.local/share/virtualenvs/text_recognition-eMREPB2y/lib/python3.9/site-packages/rest_framework/views.py", line 480, in raise_uncaught_exception
    raise exc
  File "/Users/jairajsahgal/.local/share/virtualenvs/text_recognition-eMREPB2y/lib/python3.9/site-packages/rest_framework/views.py", line 506, in dispatch
    response = handler(request, *args, **kwargs)
  File "/Users/jairajsahgal/.local/share/virtualenvs/text_recognition-eMREPB2y/lib/python3.9/site-packages/rest_framework/decorators.py", line 50, in handler
    return func(*args, **kwargs)
  File "/Users/jairajsahgal/Documents/django/text_recognition_api/text_recognition/api/views.py", line 76, in uploadImage
    serializer.save()
  File "/Users/jairajsahgal/.local/share/virtualenvs/text_recognition-eMREPB2y/lib/python3.9/site-packages/rest_framework/serializers.py", line 212, in save
    self.instance = self.create(validated_data)
  File "/Users/jairajsahgal/.local/share/virtualenvs/text_recognition-eMREPB2y/lib/python3.9/site-packages/rest_framework/serializers.py", line 962, in create
    instance = ModelClass._default_manager.create(**validated_data)
  File "/Users/jairajsahgal/.local/share/virtualenvs/text_recognition-eMREPB2y/lib/python3.9/site-packages/django/db/models/manager.py", line 85, in manager_method
    return getattr(self.get_queryset(), name)(*args, **kwargs)
  File "/Users/jairajsahgal/.local/share/virtualenvs/text_recognition-eMREPB2y/lib/python3.9/site-packages/django/db/models/query.py", line 514, in create
    obj.save(force_insert=True, using=self.db)
  File "/Users/jairajsahgal/.local/share/virtualenvs/text_recognition-eMREPB2y/lib/python3.9/site-packages/django/db/models/base.py", line 806, in save
    self.save_base(
  File "/Users/jairajsahgal/.local/share/virtualenvs/text_recognition-eMREPB2y/lib/python3.9/site-packages/django/db/models/base.py", line 857, in save_base
    updated = self._save_table(
  File "/Users/jairajsahgal/.local/share/virtualenvs/text_recognition-eMREPB2y/lib/python3.9/site-packages/django/db/models/base.py", line 1000, in _save_table
    results = self._do_insert(
  File "/Users/jairajsahgal/.local/share/virtualenvs/text_recognition-eMREPB2y/lib/python3.9/site-packages/django/db/models/base.py", line 1041, in _do_insert
    return manager._insert(
  File "/Users/jairajsahgal/.local/share/virtualenvs/text_recognition-eMREPB2y/lib/python3.9/site-packages/django/db/models/manager.py", line 85, in manager_method
    return getattr(self.get_queryset(), name)(*args, **kwargs)
  File "/Users/jairajsahgal/.local/share/virtualenvs/text_recognition-eMREPB2y/lib/python3.9/site-packages/django/db/models/query.py", line 1434, in _insert
    return query.get_compiler(using=using).execute_sql(returning_fields)
  File "/Users/jairajsahgal/.local/share/virtualenvs/text_recognition-eMREPB2y/lib/python3.9/site-packages/django/db/models/sql/compiler.py", line 1620, in execute_sql
    for sql, params in self.as_sql():
  File "/Users/jairajsahgal/.local/share/virtualenvs/text_recognition-eMREPB2y/lib/python3.9/site-packages/django/db/models/sql/compiler.py", line 1547, in as_sql
    value_rows = [
  File "/Users/jairajsahgal/.local/share/virtualenvs/text_recognition-eMREPB2y/lib/python3.9/site-packages/django/db/models/sql/compiler.py", line 1548, in <listcomp>
    [
  File "/Users/jairajsahgal/.local/share/virtualenvs/text_recognition-eMREPB2y/lib/python3.9/site-packages/django/db/models/sql/compiler.py", line 1549, in <listcomp>
    self.prepare_value(field, self.pre_save_val(field, obj))
  File "/Users/jairajsahgal/.local/share/virtualenvs/text_recognition-eMREPB2y/lib/python3.9/site-packages/django/db/models/sql/compiler.py", line 1497, in pre_save_val
    return field.pre_save(obj, add=True)
  File "/Users/jairajsahgal/.local/share/virtualenvs/text_recognition-eMREPB2y/lib/python3.9/site-packages/django/db/models/fields/files.py", line 316, in pre_save
    file.save(file.name, file.file, save=False)
  File "/Users/jairajsahgal/.local/share/virtualenvs/text_recognition-eMREPB2y/lib/python3.9/site-packages/django/db/models/fields/files.py", line 91, in save
    name = self.field.generate_filename(self.instance, name)
  File "/Users/jairajsahgal/.local/share/virtualenvs/text_recognition-eMREPB2y/lib/python3.9/site-packages/django/db/models/fields/files.py", line 331, in generate_filename
    filename = self.upload_to(instance, filename)
  File "/Users/jairajsahgal/Documents/django/text_recognition_api/text_recognition/api/models.py", line 6, in nameFile
    return '/'.join(['images', str(instance.account.username), filename])
  File "/Users/jairajsahgal/.local/share/virtualenvs/text_recognition-eMREPB2y/lib/python3.9/site-packages/django/db/models/fields/related_descriptors.py", line 215, in __get__
    raise self.RelatedObjectDoesNotExist(
api.models.Picture.account.RelatedObjectDoesNotExist: Picture has no account.
Internal Server Error: /account/upload_image/
Traceback (most recent call last):
  File "/Users/jairajsahgal/.local/share/virtualenvs/text_recognition-eMREPB2y/lib/python3.9/site-packages/django/db/backends/utils.py", line 89, in _execute
    return self.cursor.execute(sql, params)
  File "/Users/jairajsahgal/.local/share/virtualenvs/text_recognition-eMREPB2y/lib/python3.9/site-packages/django/db/backends/sqlite3/base.py", line 477, in execute
    return Database.Cursor.execute(self, query, params)
sqlite3.IntegrityError: NOT NULL constraint failed: api_picture.account_id

The above exception was the direct cause of the following exception:

Traceback (most recent call last):
  File "/Users/jairajsahgal/.local/share/virtualenvs/text_recognition-eMREPB2y/lib/python3.9/site-packages/django/core/handlers/exception.py", line 55, in inner
    response = get_response(request)
  File "/Users/jairajsahgal/.local/share/virtualenvs/text_recognition-eMREPB2y/lib/python3.9/site-packages/django/core/handlers/base.py", line 197, in _get_response
    response = wrapped_callback(request, *callback_args, **callback_kwargs)
  File "/Users/jairajsahgal/.local/share/virtualenvs/text_recognition-eMREPB2y/lib/python3.9/site-packages/django/views/decorators/csrf.py", line 54, in wrapped_view
    return view_func(*args, **kwargs)
  File "/Users/jairajsahgal/.local/share/virtualenvs/text_recognition-eMREPB2y/lib/python3.9/site-packages/django/views/generic/base.py", line 84, in view
    return self.dispatch(request, *args, **kwargs)
  File "/Users/jairajsahgal/.local/share/virtualenvs/text_recognition-eMREPB2y/lib/python3.9/site-packages/rest_framework/views.py", line 509, in dispatch
    response = self.handle_exception(exc)
  File "/Users/jairajsahgal/.local/share/virtualenvs/text_recognition-eMREPB2y/lib/python3.9/site-packages/rest_framework/views.py", line 469, in handle_exception
    self.raise_uncaught_exception(exc)
  File "/Users/jairajsahgal/.local/share/virtualenvs/text_recognition-eMREPB2y/lib/python3.9/site-packages/rest_framework/views.py", line 480, in raise_uncaught_exception
    raise exc
  File "/Users/jairajsahgal/.local/share/virtualenvs/text_recognition-eMREPB2y/lib/python3.9/site-packages/rest_framework/views.py", line 506, in dispatch
    response = handler(request, *args, **kwargs)
  File "/Users/jairajsahgal/.local/share/virtualenvs/text_recognition-eMREPB2y/lib/python3.9/site-packages/rest_framework/decorators.py", line 50, in handler
    return func(*args, **kwargs)
  File "/Users/jairajsahgal/Documents/django/text_recognition_api/text_recognition/api/views.py", line 76, in uploadImage
    serializer.save()
  File "/Users/jairajsahgal/.local/share/virtualenvs/text_recognition-eMREPB2y/lib/python3.9/site-packages/rest_framework/serializers.py", line 212, in save
    self.instance = self.create(validated_data)
  File "/Users/jairajsahgal/.local/share/virtualenvs/text_recognition-eMREPB2y/lib/python3.9/site-packages/rest_framework/serializers.py", line 962, in create
    instance = ModelClass._default_manager.create(**validated_data)
  File "/Users/jairajsahgal/.local/share/virtualenvs/text_recognition-eMREPB2y/lib/python3.9/site-packages/django/db/models/manager.py", line 85, in manager_method
    return getattr(self.get_queryset(), name)(*args, **kwargs)
  File "/Users/jairajsahgal/.local/share/virtualenvs/text_recognition-eMREPB2y/lib/python3.9/site-packages/django/db/models/query.py", line 514, in create
    obj.save(force_insert=True, using=self.db)
  File "/Users/jairajsahgal/.local/share/virtualenvs/text_recognition-eMREPB2y/lib/python3.9/site-packages/django/db/models/base.py", line 806, in save
    self.save_base(
  File "/Users/jairajsahgal/.local/share/virtualenvs/text_recognition-eMREPB2y/lib/python3.9/site-packages/django/db/models/base.py", line 857, in save_base
    updated = self._save_table(
  File "/Users/jairajsahgal/.local/share/virtualenvs/text_recognition-eMREPB2y/lib/python3.9/site-packages/django/db/models/base.py", line 1000, in _save_table
    results = self._do_insert(
  File "/Users/jairajsahgal/.local/share/virtualenvs/text_recognition-eMREPB2y/lib/python3.9/site-packages/django/db/models/base.py", line 1041, in _do_insert
    return manager._insert(
  File "/Users/jairajsahgal/.local/share/virtualenvs/text_recognition-eMREPB2y/lib/python3.9/site-packages/django/db/models/manager.py", line 85, in manager_method
    return getattr(self.get_queryset(), name)(*args, **kwargs)
  File "/Users/jairajsahgal/.local/share/virtualenvs/text_recognition-eMREPB2y/lib/python3.9/site-packages/django/db/models/query.py", line 1434, in _insert
    return query.get_compiler(using=using).execute_sql(returning_fields)
  File "/Users/jairajsahgal/.local/share/virtualenvs/text_recognition-eMREPB2y/lib/python3.9/site-packages/django/db/models/sql/compiler.py", line 1621, in execute_sql
    cursor.execute(sql, params)
  File "/Users/jairajsahgal/.local/share/virtualenvs/text_recognition-eMREPB2y/lib/python3.9/site-packages/django/db/backends/utils.py", line 103, in execute
    return super().execute(sql, params)
  File "/Users/jairajsahgal/.local/share/virtualenvs/text_recognition-eMREPB2y/lib/python3.9/site-packages/django/db/backends/utils.py", line 67, in execute
    return self._execute_with_wrappers(
  File "/Users/jairajsahgal/.local/share/virtualenvs/text_recognition-eMREPB2y/lib/python3.9/site-packages/django/db/backends/utils.py", line 80, in _execute_with_wrappers
    return executor(sql, params, many, context)
  File "/Users/jairajsahgal/.local/share/virtualenvs/text_recognition-eMREPB2y/lib/python3.9/site-packages/django/db/backends/utils.py", line 89, in _execute
    return self.cursor.execute(sql, params)
  File "/Users/jairajsahgal/.local/share/virtualenvs/text_recognition-eMREPB2y/lib/python3.9/site-packages/django/db/utils.py", line 91, in __exit__
    raise dj_exc_value.with_traceback(traceback) from exc_value
  File "/Users/jairajsahgal/.local/share/virtualenvs/text_recognition-eMREPB2y/lib/python3.9/site-packages/django/db/backends/utils.py", line 89, in _execute
    return self.cursor.execute(sql, params)
  File "/Users/jairajsahgal/.local/share/virtualenvs/text_recognition-eMREPB2y/lib/python3.9/site-packages/django/db/backends/sqlite3/base.py", line 477, in execute
    return Database.Cursor.execute(self, query, params)
django.db.utils.IntegrityError: NOT NULL constraint failed: api_picture.account_id
Internal Server Error: /account/upload_image/
Traceback (most recent call last):
  File "/Users/jairajsahgal/.local/share/virtualenvs/text_recognition-eMREPB2y/lib/python3.9/site-packages/django/db/backends/utils.py", line 89, in _execute
    return self.cursor.execute(sql, params)
  File "/Users/jairajsahgal/.local/share/virtualenvs/text_recognition-eMREPB2y/lib/python3.9/site-packages/django/db/backends/sqlite3/base.py", line 477, in execute
    return Database.Cursor.execute(self, query, params)
sqlite3.IntegrityError: NOT NULL constraint failed: api_picture.account_id

The above exception was the direct cause of the following exception:

Traceback (most recent call last):
  File "/Users/jairajsahgal/.local/share/virtualenvs/text_recognition-eMREPB2y/lib/python3.9/site-packages/django/core/handlers/exception.py", line 55, in inner
    response = get_response(request)
  File "/Users/jairajsahgal/.local/share/virtualenvs/text_recognition-eMREPB2y/lib/python3.9/site-packages/django/core/handlers/base.py", line 197, in _get_response
    response = wrapped_callback(request, *callback_args, **callback_kwargs)
  File "/Users/jairajsahgal/.local/share/virtualenvs/text_recognition-eMREPB2y/lib/python3.9/site-packages/django/views/decorators/csrf.py", line 54, in wrapped_view
    return view_func(*args, **kwargs)
  File "/Users/jairajsahgal/.local/share/virtualenvs/text_recognition-eMREPB2y/lib/python3.9/site-packages/django/views/generic/base.py", line 84, in view
    return self.dispatch(request, *args, **kwargs)
  File "/Users/jairajsahgal/.local/share/virtualenvs/text_recognition-eMREPB2y/lib/python3.9/site-packages/rest_framework/views.py", line 509, in dispatch
    response = self.handle_exception(exc)
  File "/Users/jairajsahgal/.local/share/virtualenvs/text_recognition-eMREPB2y/lib/python3.9/site-packages/rest_framework/views.py", line 469, in handle_exception
    self.raise_uncaught_exception(exc)
  File "/Users/jairajsahgal/.local/share/virtualenvs/text_recognition-eMREPB2y/lib/python3.9/site-packages/rest_framework/views.py", line 480, in raise_uncaught_exception
    raise exc
  File "/Users/jairajsahgal/.local/share/virtualenvs/text_recognition-eMREPB2y/lib/python3.9/site-packages/rest_framework/views.py", line 506, in dispatch
    response = handler(request, *args, **kwargs)
  File "/Users/jairajsahgal/.local/share/virtualenvs/text_recognition-eMREPB2y/lib/python3.9/site-packages/rest_framework/decorators.py", line 50, in handler
    return func(*args, **kwargs)
  File "/Users/jairajsahgal/Documents/django/text_recognition_api/text_recognition/api/views.py", line 76, in uploadImage
    serializer.save()
  File "/Users/jairajsahgal/.local/share/virtualenvs/text_recognition-eMREPB2y/lib/python3.9/site-packages/rest_framework/serializers.py", line 212, in save
    self.instance = self.create(validated_data)
  File "/Users/jairajsahgal/.local/share/virtualenvs/text_recognition-eMREPB2y/lib/python3.9/site-packages/rest_framework/serializers.py", line 962, in create
    instance = ModelClass._default_manager.create(**validated_data)
  File "/Users/jairajsahgal/.local/share/virtualenvs/text_recognition-eMREPB2y/lib/python3.9/site-packages/django/db/models/manager.py", line 85, in manager_method
    return getattr(self.get_queryset(), name)(*args, **kwargs)
  File "/Users/jairajsahgal/.local/share/virtualenvs/text_recognition-eMREPB2y/lib/python3.9/site-packages/django/db/models/query.py", line 514, in create
    obj.save(force_insert=True, using=self.db)
  File "/Users/jairajsahgal/.local/share/virtualenvs/text_recognition-eMREPB2y/lib/python3.9/site-packages/django/db/models/base.py", line 806, in save
    self.save_base(
  File "/Users/jairajsahgal/.local/share/virtualenvs/text_recognition-eMREPB2y/lib/python3.9/site-packages/django/db/models/base.py", line 857, in save_base
    updated = self._save_table(
  File "/Users/jairajsahgal/.local/share/virtualenvs/text_recognition-eMREPB2y/lib/python3.9/site-packages/django/db/models/base.py", line 1000, in _save_table
    results = self._do_insert(
  File "/Users/jairajsahgal/.local/share/virtualenvs/text_recognition-eMREPB2y/lib/python3.9/site-packages/django/db/models/base.py", line 1041, in _do_insert
    return manager._insert(
  File "/Users/jairajsahgal/.local/share/virtualenvs/text_recognition-eMREPB2y/lib/python3.9/site-packages/django/db/models/manager.py", line 85, in manager_method
    return getattr(self.get_queryset(), name)(*args, **kwargs)
  File "/Users/jairajsahgal/.local/share/virtualenvs/text_recognition-eMREPB2y/lib/python3.9/site-packages/django/db/models/query.py", line 1434, in _insert
    return query.get_compiler(using=using).execute_sql(returning_fields)
  File "/Users/jairajsahgal/.local/share/virtualenvs/text_recognition-eMREPB2y/lib/python3.9/site-packages/django/db/models/sql/compiler.py", line 1621, in execute_sql
    cursor.execute(sql, params)
  File "/Users/jairajsahgal/.local/share/virtualenvs/text_recognition-eMREPB2y/lib/python3.9/site-packages/django/db/backends/utils.py", line 103, in execute
    return super().execute(sql, params)
  File "/Users/jairajsahgal/.local/share/virtualenvs/text_recognition-eMREPB2y/lib/python3.9/site-packages/django/db/backends/utils.py", line 67, in execute
    return self._execute_with_wrappers(
  File "/Users/jairajsahgal/.local/share/virtualenvs/text_recognition-eMREPB2y/lib/python3.9/site-packages/django/db/backends/utils.py", line 80, in _execute_with_wrappers
    return executor(sql, params, many, context)
  File "/Users/jairajsahgal/.local/share/virtualenvs/text_recognition-eMREPB2y/lib/python3.9/site-packages/django/db/backends/utils.py", line 89, in _execute
    return self.cursor.execute(sql, params)
  File "/Users/jairajsahgal/.local/share/virtualenvs/text_recognition-eMREPB2y/lib/python3.9/site-packages/django/db/utils.py", line 91, in __exit__
    raise dj_exc_value.with_traceback(traceback) from exc_value
  File "/Users/jairajsahgal/.local/share/virtualenvs/text_recognition-eMREPB2y/lib/python3.9/site-packages/django/db/backends/utils.py", line 89, in _execute
    return self.cursor.execute(sql, params)
  File "/Users/jairajsahgal/.local/share/virtualenvs/text_recognition-eMREPB2y/lib/python3.9/site-packages/django/db/backends/sqlite3/base.py", line 477, in execute
    return Database.Cursor.execute(self, query, params)
django.db.utils.IntegrityError: NOT NULL constraint failed: api_picture.account_id
Unauthorized: /account/upload_image/
Bad Request: /account/login/
Bad Request: /account/login/
Bad Request: /account/login/
Unauthorized: /account/upload_image/
Bad Request: /account/login/
Bad Request: /account/login/
Internal Server Error: /account/login/
Traceback (most recent call last):
  File "/Users/jairajsahgal/.local/share/virtualenvs/text_recognition-eMREPB2y/lib/python3.9/site-packages/django/core/handlers/exception.py", line 55, in inner
    response = get_response(request)
  File "/Users/jairajsahgal/.local/share/virtualenvs/text_recognition-eMREPB2y/lib/python3.9/site-packages/django/core/handlers/base.py", line 197, in _get_response
    response = wrapped_callback(request, *callback_args, **callback_kwargs)
  File "/Users/jairajsahgal/.local/share/virtualenvs/text_recognition-eMREPB2y/lib/python3.9/site-packages/django/views/decorators/csrf.py", line 54, in wrapped_view
    return view_func(*args, **kwargs)
  File "/Users/jairajsahgal/.local/share/virtualenvs/text_recognition-eMREPB2y/lib/python3.9/site-packages/django/views/generic/base.py", line 84, in view
    return self.dispatch(request, *args, **kwargs)
  File "/Users/jairajsahgal/.local/share/virtualenvs/text_recognition-eMREPB2y/lib/python3.9/site-packages/rest_framework/views.py", line 509, in dispatch
    response = self.handle_exception(exc)
  File "/Users/jairajsahgal/.local/share/virtualenvs/text_recognition-eMREPB2y/lib/python3.9/site-packages/rest_framework/views.py", line 469, in handle_exception
    self.raise_uncaught_exception(exc)
  File "/Users/jairajsahgal/.local/share/virtualenvs/text_recognition-eMREPB2y/lib/python3.9/site-packages/rest_framework/views.py", line 480, in raise_uncaught_exception
    raise exc
  File "/Users/jairajsahgal/.local/share/virtualenvs/text_recognition-eMREPB2y/lib/python3.9/site-packages/rest_framework/views.py", line 506, in dispatch
    response = handler(request, *args, **kwargs)
  File "/Users/jairajsahgal/.local/share/virtualenvs/text_recognition-eMREPB2y/lib/python3.9/site-packages/rest_framework/decorators.py", line 50, in handler
    return func(*args, **kwargs)
  File "/Users/jairajsahgal/Documents/django/text_recognition_api/text_recognition/api/views.py", line 66, in login_account
    if serializer.is_valid():
  File "/Users/jairajsahgal/.local/share/virtualenvs/text_recognition-eMREPB2y/lib/python3.9/site-packages/rest_framework/serializers.py", line 220, in is_valid
    assert hasattr(self, 'initial_data'), (
AssertionError: Cannot call `.is_valid()` as no `data=` keyword argument was passed when instantiating the serializer instance.
Internal Server Error: /account/login/
Traceback (most recent call last):
  File "/Users/jairajsahgal/.local/share/virtualenvs/text_recognition-eMREPB2y/lib/python3.9/site-packages/django/core/handlers/exception.py", line 55, in inner
    response = get_response(request)
  File "/Users/jairajsahgal/.local/share/virtualenvs/text_recognition-eMREPB2y/lib/python3.9/site-packages/django/core/handlers/base.py", line 197, in _get_response
    response = wrapped_callback(request, *callback_args, **callback_kwargs)
  File "/Users/jairajsahgal/.local/share/virtualenvs/text_recognition-eMREPB2y/lib/python3.9/site-packages/django/views/decorators/csrf.py", line 54, in wrapped_view
    return view_func(*args, **kwargs)
  File "/Users/jairajsahgal/.local/share/virtualenvs/text_recognition-eMREPB2y/lib/python3.9/site-packages/django/views/generic/base.py", line 84, in view
    return self.dispatch(request, *args, **kwargs)
  File "/Users/jairajsahgal/.local/share/virtualenvs/text_recognition-eMREPB2y/lib/python3.9/site-packages/rest_framework/views.py", line 509, in dispatch
    response = self.handle_exception(exc)
  File "/Users/jairajsahgal/.local/share/virtualenvs/text_recognition-eMREPB2y/lib/python3.9/site-packages/rest_framework/views.py", line 469, in handle_exception
    self.raise_uncaught_exception(exc)
  File "/Users/jairajsahgal/.local/share/virtualenvs/text_recognition-eMREPB2y/lib/python3.9/site-packages/rest_framework/views.py", line 480, in raise_uncaught_exception
    raise exc
  File "/Users/jairajsahgal/.local/share/virtualenvs/text_recognition-eMREPB2y/lib/python3.9/site-packages/rest_framework/views.py", line 506, in dispatch
    response = handler(request, *args, **kwargs)
  File "/Users/jairajsahgal/.local/share/virtualenvs/text_recognition-eMREPB2y/lib/python3.9/site-packages/rest_framework/decorators.py", line 50, in handler
    return func(*args, **kwargs)
  File "/Users/jairajsahgal/Documents/django/text_recognition_api/text_recognition/api/views.py", line 66, in login_account
    if serializer.is_valid():
  File "/Users/jairajsahgal/.local/share/virtualenvs/text_recognition-eMREPB2y/lib/python3.9/site-packages/rest_framework/serializers.py", line 220, in is_valid
    assert hasattr(self, 'initial_data'), (
AssertionError: Cannot call `.is_valid()` as no `data=` keyword argument was passed when instantiating the serializer instance.
Internal Server Error: /account/login/
Traceback (most recent call last):
  File "/Users/jairajsahgal/.local/share/virtualenvs/text_recognition-eMREPB2y/lib/python3.9/site-packages/django/core/handlers/exception.py", line 55, in inner
    response = get_response(request)
  File "/Users/jairajsahgal/.local/share/virtualenvs/text_recognition-eMREPB2y/lib/python3.9/site-packages/django/core/handlers/base.py", line 197, in _get_response
    response = wrapped_callback(request, *callback_args, **callback_kwargs)
  File "/Users/jairajsahgal/.local/share/virtualenvs/text_recognition-eMREPB2y/lib/python3.9/site-packages/django/views/decorators/csrf.py", line 54, in wrapped_view
    return view_func(*args, **kwargs)
  File "/Users/jairajsahgal/.local/share/virtualenvs/text_recognition-eMREPB2y/lib/python3.9/site-packages/django/views/generic/base.py", line 84, in view
    return self.dispatch(request, *args, **kwargs)
  File "/Users/jairajsahgal/.local/share/virtualenvs/text_recognition-eMREPB2y/lib/python3.9/site-packages/rest_framework/views.py", line 509, in dispatch
    response = self.handle_exception(exc)
  File "/Users/jairajsahgal/.local/share/virtualenvs/text_recognition-eMREPB2y/lib/python3.9/site-packages/rest_framework/views.py", line 469, in handle_exception
    self.raise_uncaught_exception(exc)
  File "/Users/jairajsahgal/.local/share/virtualenvs/text_recognition-eMREPB2y/lib/python3.9/site-packages/rest_framework/views.py", line 480, in raise_uncaught_exception
    raise exc
  File "/Users/jairajsahgal/.local/share/virtualenvs/text_recognition-eMREPB2y/lib/python3.9/site-packages/rest_framework/views.py", line 506, in dispatch
    response = handler(request, *args, **kwargs)
  File "/Users/jairajsahgal/.local/share/virtualenvs/text_recognition-eMREPB2y/lib/python3.9/site-packages/rest_framework/decorators.py", line 50, in handler
    return func(*args, **kwargs)
  File "/Users/jairajsahgal/Documents/django/text_recognition_api/text_recognition/api/views.py", line 66, in login_account
    userObject = authenticate(request=request,email=serializer.validated_data["email"],password=serializer.validated_data["password"])
  File "/Users/jairajsahgal/.local/share/virtualenvs/text_recognition-eMREPB2y/lib/python3.9/site-packages/rest_framework/serializers.py", line 271, in validated_data
    raise AssertionError(msg)
AssertionError: You must call `.is_valid()` before accessing `.validated_data`.
Internal Server Error: /account/login/
Traceback (most recent call last):
  File "/Users/jairajsahgal/.local/share/virtualenvs/text_recognition-eMREPB2y/lib/python3.9/site-packages/django/core/handlers/exception.py", line 55, in inner
    response = get_response(request)
  File "/Users/jairajsahgal/.local/share/virtualenvs/text_recognition-eMREPB2y/lib/python3.9/site-packages/django/core/handlers/base.py", line 197, in _get_response
    response = wrapped_callback(request, *callback_args, **callback_kwargs)
  File "/Users/jairajsahgal/.local/share/virtualenvs/text_recognition-eMREPB2y/lib/python3.9/site-packages/django/views/decorators/csrf.py", line 54, in wrapped_view
    return view_func(*args, **kwargs)
  File "/Users/jairajsahgal/.local/share/virtualenvs/text_recognition-eMREPB2y/lib/python3.9/site-packages/django/views/generic/base.py", line 84, in view
    return self.dispatch(request, *args, **kwargs)
  File "/Users/jairajsahgal/.local/share/virtualenvs/text_recognition-eMREPB2y/lib/python3.9/site-packages/rest_framework/views.py", line 509, in dispatch
    response = self.handle_exception(exc)
  File "/Users/jairajsahgal/.local/share/virtualenvs/text_recognition-eMREPB2y/lib/python3.9/site-packages/rest_framework/views.py", line 469, in handle_exception
    self.raise_uncaught_exception(exc)
  File "/Users/jairajsahgal/.local/share/virtualenvs/text_recognition-eMREPB2y/lib/python3.9/site-packages/rest_framework/views.py", line 480, in raise_uncaught_exception
    raise exc
  File "/Users/jairajsahgal/.local/share/virtualenvs/text_recognition-eMREPB2y/lib/python3.9/site-packages/rest_framework/views.py", line 506, in dispatch
    response = handler(request, *args, **kwargs)
  File "/Users/jairajsahgal/.local/share/virtualenvs/text_recognition-eMREPB2y/lib/python3.9/site-packages/rest_framework/decorators.py", line 50, in handler
    return func(*args, **kwargs)
  File "/Users/jairajsahgal/Documents/django/text_recognition_api/text_recognition/api/views.py", line 66, in login_account
    if serializer.is_valid():
  File "/Users/jairajsahgal/.local/share/virtualenvs/text_recognition-eMREPB2y/lib/python3.9/site-packages/rest_framework/serializers.py", line 220, in is_valid
    assert hasattr(self, 'initial_data'), (
AssertionError: Cannot call `.is_valid()` as no `data=` keyword argument was passed when instantiating the serializer instance.
Internal Server Error: /account/login/
Traceback (most recent call last):
  File "/Users/jairajsahgal/.local/share/virtualenvs/text_recognition-eMREPB2y/lib/python3.9/site-packages/django/core/handlers/exception.py", line 55, in inner
    response = get_response(request)
  File "/Users/jairajsahgal/.local/share/virtualenvs/text_recognition-eMREPB2y/lib/python3.9/site-packages/django/core/handlers/base.py", line 197, in _get_response
    response = wrapped_callback(request, *callback_args, **callback_kwargs)
  File "/Users/jairajsahgal/.local/share/virtualenvs/text_recognition-eMREPB2y/lib/python3.9/site-packages/django/views/decorators/csrf.py", line 54, in wrapped_view
    return view_func(*args, **kwargs)
  File "/Users/jairajsahgal/.local/share/virtualenvs/text_recognition-eMREPB2y/lib/python3.9/site-packages/django/views/generic/base.py", line 84, in view
    return self.dispatch(request, *args, **kwargs)
  File "/Users/jairajsahgal/.local/share/virtualenvs/text_recognition-eMREPB2y/lib/python3.9/site-packages/rest_framework/views.py", line 509, in dispatch
    response = self.handle_exception(exc)
  File "/Users/jairajsahgal/.local/share/virtualenvs/text_recognition-eMREPB2y/lib/python3.9/site-packages/rest_framework/views.py", line 469, in handle_exception
    self.raise_uncaught_exception(exc)
  File "/Users/jairajsahgal/.local/share/virtualenvs/text_recognition-eMREPB2y/lib/python3.9/site-packages/rest_framework/views.py", line 480, in raise_uncaught_exception
    raise exc
  File "/Users/jairajsahgal/.local/share/virtualenvs/text_recognition-eMREPB2y/lib/python3.9/site-packages/rest_framework/views.py", line 506, in dispatch
    response = handler(request, *args, **kwargs)
  File "/Users/jairajsahgal/.local/share/virtualenvs/text_recognition-eMREPB2y/lib/python3.9/site-packages/rest_framework/decorators.py", line 50, in handler
    return func(*args, **kwargs)
  File "/Users/jairajsahgal/Documents/django/text_recognition_api/text_recognition/api/views.py", line 67, in login_account
    if serializer.is_valid():
  File "/Users/jairajsahgal/.local/share/virtualenvs/text_recognition-eMREPB2y/lib/python3.9/site-packages/rest_framework/serializers.py", line 220, in is_valid
    assert hasattr(self, 'initial_data'), (
AssertionError: Cannot call `.is_valid()` as no `data=` keyword argument was passed when instantiating the serializer instance.
Internal Server Error: /account/login/
Traceback (most recent call last):
  File "/Users/jairajsahgal/.local/share/virtualenvs/text_recognition-eMREPB2y/lib/python3.9/site-packages/django/core/handlers/exception.py", line 55, in inner
    response = get_response(request)
  File "/Users/jairajsahgal/.local/share/virtualenvs/text_recognition-eMREPB2y/lib/python3.9/site-packages/django/core/handlers/base.py", line 197, in _get_response
    response = wrapped_callback(request, *callback_args, **callback_kwargs)
  File "/Users/jairajsahgal/.local/share/virtualenvs/text_recognition-eMREPB2y/lib/python3.9/site-packages/django/views/decorators/csrf.py", line 54, in wrapped_view
    return view_func(*args, **kwargs)
  File "/Users/jairajsahgal/.local/share/virtualenvs/text_recognition-eMREPB2y/lib/python3.9/site-packages/django/views/generic/base.py", line 84, in view
    return self.dispatch(request, *args, **kwargs)
  File "/Users/jairajsahgal/.local/share/virtualenvs/text_recognition-eMREPB2y/lib/python3.9/site-packages/rest_framework/views.py", line 511, in dispatch
    self.response = self.finalize_response(request, response, *args, **kwargs)
  File "/Users/jairajsahgal/.local/share/virtualenvs/text_recognition-eMREPB2y/lib/python3.9/site-packages/rest_framework/views.py", line 423, in finalize_response
    assert isinstance(response, HttpResponseBase), (
AssertionError: Expected a `Response`, `HttpResponse` or `HttpStreamingResponse` to be returned from the view, but received a `<class 'NoneType'>`
Internal Server Error: /account/login/
Traceback (most recent call last):
  File "/Users/jairajsahgal/.local/share/virtualenvs/text_recognition-eMREPB2y/lib/python3.9/site-packages/django/utils/datastructures.py", line 84, in __getitem__
    list_ = super().__getitem__(key)
KeyError: 'password'

During handling of the above exception, another exception occurred:

Traceback (most recent call last):
  File "/Users/jairajsahgal/.local/share/virtualenvs/text_recognition-eMREPB2y/lib/python3.9/site-packages/rest_framework/fields.py", line 457, in get_attribute
    return get_attribute(instance, self.source_attrs)
  File "/Users/jairajsahgal/.local/share/virtualenvs/text_recognition-eMREPB2y/lib/python3.9/site-packages/rest_framework/fields.py", line 95, in get_attribute
    instance = instance[attr]
  File "/Users/jairajsahgal/.local/share/virtualenvs/text_recognition-eMREPB2y/lib/python3.9/site-packages/django/utils/datastructures.py", line 86, in __getitem__
    raise MultiValueDictKeyError(key)
django.utils.datastructures.MultiValueDictKeyError: 'password'

During handling of the above exception, another exception occurred:

Traceback (most recent call last):
  File "/Users/jairajsahgal/.local/share/virtualenvs/text_recognition-eMREPB2y/lib/python3.9/site-packages/django/core/handlers/exception.py", line 55, in inner
    response = get_response(request)
  File "/Users/jairajsahgal/.local/share/virtualenvs/text_recognition-eMREPB2y/lib/python3.9/site-packages/django/core/handlers/base.py", line 197, in _get_response
    response = wrapped_callback(request, *callback_args, **callback_kwargs)
  File "/Users/jairajsahgal/.local/share/virtualenvs/text_recognition-eMREPB2y/lib/python3.9/site-packages/django/views/decorators/csrf.py", line 54, in wrapped_view
    return view_func(*args, **kwargs)
  File "/Users/jairajsahgal/.local/share/virtualenvs/text_recognition-eMREPB2y/lib/python3.9/site-packages/django/views/generic/base.py", line 84, in view
    return self.dispatch(request, *args, **kwargs)
  File "/Users/jairajsahgal/.local/share/virtualenvs/text_recognition-eMREPB2y/lib/python3.9/site-packages/rest_framework/views.py", line 509, in dispatch
    response = self.handle_exception(exc)
  File "/Users/jairajsahgal/.local/share/virtualenvs/text_recognition-eMREPB2y/lib/python3.9/site-packages/rest_framework/views.py", line 469, in handle_exception
    self.raise_uncaught_exception(exc)
  File "/Users/jairajsahgal/.local/share/virtualenvs/text_recognition-eMREPB2y/lib/python3.9/site-packages/rest_framework/views.py", line 480, in raise_uncaught_exception
    raise exc
  File "/Users/jairajsahgal/.local/share/virtualenvs/text_recognition-eMREPB2y/lib/python3.9/site-packages/rest_framework/views.py", line 506, in dispatch
    response = handler(request, *args, **kwargs)
  File "/Users/jairajsahgal/.local/share/virtualenvs/text_recognition-eMREPB2y/lib/python3.9/site-packages/rest_framework/decorators.py", line 50, in handler
    return func(*args, **kwargs)
  File "/Users/jairajsahgal/Documents/django/text_recognition_api/text_recognition/api/views.py", line 66, in login_account
    logger.info(serializer.data)
  File "/Users/jairajsahgal/.local/share/virtualenvs/text_recognition-eMREPB2y/lib/python3.9/site-packages/rest_framework/serializers.py", line 555, in data
    ret = super().data
  File "/Users/jairajsahgal/.local/share/virtualenvs/text_recognition-eMREPB2y/lib/python3.9/site-packages/rest_framework/serializers.py", line 253, in data
    self._data = self.to_representation(self.instance)
  File "/Users/jairajsahgal/.local/share/virtualenvs/text_recognition-eMREPB2y/lib/python3.9/site-packages/rest_framework/serializers.py", line 509, in to_representation
    attribute = field.get_attribute(instance)
  File "/Users/jairajsahgal/.local/share/virtualenvs/text_recognition-eMREPB2y/lib/python3.9/site-packages/rest_framework/fields.py", line 490, in get_attribute
    raise type(exc)(msg)
django.utils.datastructures.MultiValueDictKeyError: "Got MultiValueDictKeyError when attempting to get a value for field `password` on serializer `LoginSerializer`.\nThe serializer field might be named incorrectly and not match any attribute or key on the `QueryDict` instance.\nOriginal exception text was: 'password'."
Internal Server Error: /account/login/
Traceback (most recent call last):
  File "/Users/jairajsahgal/.local/share/virtualenvs/text_recognition-eMREPB2y/lib/python3.9/site-packages/django/core/handlers/exception.py", line 55, in inner
    response = get_response(request)
  File "/Users/jairajsahgal/.local/share/virtualenvs/text_recognition-eMREPB2y/lib/python3.9/site-packages/django/core/handlers/base.py", line 197, in _get_response
    response = wrapped_callback(request, *callback_args, **callback_kwargs)
  File "/Users/jairajsahgal/.local/share/virtualenvs/text_recognition-eMREPB2y/lib/python3.9/site-packages/django/views/decorators/csrf.py", line 54, in wrapped_view
    return view_func(*args, **kwargs)
  File "/Users/jairajsahgal/.local/share/virtualenvs/text_recognition-eMREPB2y/lib/python3.9/site-packages/django/views/generic/base.py", line 84, in view
    return self.dispatch(request, *args, **kwargs)
  File "/Users/jairajsahgal/.local/share/virtualenvs/text_recognition-eMREPB2y/lib/python3.9/site-packages/rest_framework/views.py", line 509, in dispatch
    response = self.handle_exception(exc)
  File "/Users/jairajsahgal/.local/share/virtualenvs/text_recognition-eMREPB2y/lib/python3.9/site-packages/rest_framework/views.py", line 469, in handle_exception
    self.raise_uncaught_exception(exc)
  File "/Users/jairajsahgal/.local/share/virtualenvs/text_recognition-eMREPB2y/lib/python3.9/site-packages/rest_framework/views.py", line 480, in raise_uncaught_exception
    raise exc
  File "/Users/jairajsahgal/.local/share/virtualenvs/text_recognition-eMREPB2y/lib/python3.9/site-packages/rest_framework/views.py", line 506, in dispatch
    response = handler(request, *args, **kwargs)
  File "/Users/jairajsahgal/.local/share/virtualenvs/text_recognition-eMREPB2y/lib/python3.9/site-packages/rest_framework/decorators.py", line 50, in handler
    return func(*args, **kwargs)
  File "/Users/jairajsahgal/Documents/django/text_recognition_api/text_recognition/api/views.py", line 66, in login_account
    if serializer.is_valid(raise_exception=True):
  File "/Users/jairajsahgal/.local/share/virtualenvs/text_recognition-eMREPB2y/lib/python3.9/site-packages/rest_framework/serializers.py", line 227, in is_valid
    self._validated_data = self.run_validation(self.initial_data)
  File "/Users/jairajsahgal/.local/share/virtualenvs/text_recognition-eMREPB2y/lib/python3.9/site-packages/rest_framework/serializers.py", line 426, in run_validation
    value = self.to_internal_value(data)
  File "/Users/jairajsahgal/.local/share/virtualenvs/text_recognition-eMREPB2y/lib/python3.9/site-packages/rest_framework/serializers.py", line 479, in to_internal_value
    for field in fields:
  File "/Users/jairajsahgal/.local/share/virtualenvs/text_recognition-eMREPB2y/lib/python3.9/site-packages/rest_framework/serializers.py", line 362, in _writable_fields
    for field in self.fields.values():
  File "/Users/jairajsahgal/.local/share/virtualenvs/text_recognition-eMREPB2y/lib/python3.9/site-packages/django/utils/functional.py", line 49, in __get__
    res = instance.__dict__[self.name] = self.func(instance)
  File "/Users/jairajsahgal/.local/share/virtualenvs/text_recognition-eMREPB2y/lib/python3.9/site-packages/rest_framework/serializers.py", line 356, in fields
    for key, value in self.get_fields().items():
  File "/Users/jairajsahgal/.local/share/virtualenvs/text_recognition-eMREPB2y/lib/python3.9/site-packages/rest_framework/serializers.py", line 1076, in get_fields
    field_class, field_kwargs = self.build_field(
  File "/Users/jairajsahgal/.local/share/virtualenvs/text_recognition-eMREPB2y/lib/python3.9/site-packages/rest_framework/serializers.py", line 1222, in build_field
    return self.build_unknown_field(field_name, model_class)
  File "/Users/jairajsahgal/.local/share/virtualenvs/text_recognition-eMREPB2y/lib/python3.9/site-packages/rest_framework/serializers.py", line 1340, in build_unknown_field
    raise ImproperlyConfigured(
django.core.exceptions.ImproperlyConfigured: Field name `password` is not valid for model `Account`.
Internal Server Error: /account/login/
Traceback (most recent call last):
  File "/Users/jairajsahgal/.local/share/virtualenvs/text_recognition-eMREPB2y/lib/python3.9/site-packages/django/core/handlers/exception.py", line 55, in inner
    response = get_response(request)
  File "/Users/jairajsahgal/.local/share/virtualenvs/text_recognition-eMREPB2y/lib/python3.9/site-packages/django/core/handlers/base.py", line 197, in _get_response
    response = wrapped_callback(request, *callback_args, **callback_kwargs)
  File "/Users/jairajsahgal/.local/share/virtualenvs/text_recognition-eMREPB2y/lib/python3.9/site-packages/django/views/decorators/csrf.py", line 54, in wrapped_view
    return view_func(*args, **kwargs)
  File "/Users/jairajsahgal/.local/share/virtualenvs/text_recognition-eMREPB2y/lib/python3.9/site-packages/django/views/generic/base.py", line 84, in view
    return self.dispatch(request, *args, **kwargs)
  File "/Users/jairajsahgal/.local/share/virtualenvs/text_recognition-eMREPB2y/lib/python3.9/site-packages/rest_framework/views.py", line 509, in dispatch
    response = self.handle_exception(exc)
  File "/Users/jairajsahgal/.local/share/virtualenvs/text_recognition-eMREPB2y/lib/python3.9/site-packages/rest_framework/views.py", line 469, in handle_exception
    self.raise_uncaught_exception(exc)
  File "/Users/jairajsahgal/.local/share/virtualenvs/text_recognition-eMREPB2y/lib/python3.9/site-packages/rest_framework/views.py", line 480, in raise_uncaught_exception
    raise exc
  File "/Users/jairajsahgal/.local/share/virtualenvs/text_recognition-eMREPB2y/lib/python3.9/site-packages/rest_framework/views.py", line 506, in dispatch
    response = handler(request, *args, **kwargs)
  File "/Users/jairajsahgal/.local/share/virtualenvs/text_recognition-eMREPB2y/lib/python3.9/site-packages/rest_framework/decorators.py", line 50, in handler
    return func(*args, **kwargs)
  File "/Users/jairajsahgal/Documents/django/text_recognition_api/text_recognition/api/views.py", line 66, in login_account
    if serializer.is_valid(raise_exception=True):
  File "/Users/jairajsahgal/.local/share/virtualenvs/text_recognition-eMREPB2y/lib/python3.9/site-packages/rest_framework/serializers.py", line 227, in is_valid
    self._validated_data = self.run_validation(self.initial_data)
  File "/Users/jairajsahgal/.local/share/virtualenvs/text_recognition-eMREPB2y/lib/python3.9/site-packages/rest_framework/serializers.py", line 426, in run_validation
    value = self.to_internal_value(data)
  File "/Users/jairajsahgal/.local/share/virtualenvs/text_recognition-eMREPB2y/lib/python3.9/site-packages/rest_framework/serializers.py", line 479, in to_internal_value
    for field in fields:
  File "/Users/jairajsahgal/.local/share/virtualenvs/text_recognition-eMREPB2y/lib/python3.9/site-packages/rest_framework/serializers.py", line 362, in _writable_fields
    for field in self.fields.values():
  File "/Users/jairajsahgal/.local/share/virtualenvs/text_recognition-eMREPB2y/lib/python3.9/site-packages/django/utils/functional.py", line 49, in __get__
    res = instance.__dict__[self.name] = self.func(instance)
  File "/Users/jairajsahgal/.local/share/virtualenvs/text_recognition-eMREPB2y/lib/python3.9/site-packages/rest_framework/serializers.py", line 356, in fields
    for key, value in self.get_fields().items():
  File "/Users/jairajsahgal/.local/share/virtualenvs/text_recognition-eMREPB2y/lib/python3.9/site-packages/rest_framework/serializers.py", line 1052, in get_fields
    field_names = self.get_field_names(declared_fields, info)
  File "/Users/jairajsahgal/.local/share/virtualenvs/text_recognition-eMREPB2y/lib/python3.9/site-packages/rest_framework/serializers.py", line 1148, in get_field_names
    assert field_name in fields, (
AssertionError: The field 'password' was declared on serializer LoginSerializer, but has not been included in the 'fields' option.
Internal Server Error: /account/login/
Traceback (most recent call last):
  File "/Users/jairajsahgal/.local/share/virtualenvs/text_recognition-eMREPB2y/lib/python3.9/site-packages/django/core/handlers/exception.py", line 55, in inner
    response = get_response(request)
  File "/Users/jairajsahgal/.local/share/virtualenvs/text_recognition-eMREPB2y/lib/python3.9/site-packages/django/core/handlers/base.py", line 197, in _get_response
    response = wrapped_callback(request, *callback_args, **callback_kwargs)
  File "/Users/jairajsahgal/.local/share/virtualenvs/text_recognition-eMREPB2y/lib/python3.9/site-packages/django/views/decorators/csrf.py", line 54, in wrapped_view
    return view_func(*args, **kwargs)
  File "/Users/jairajsahgal/.local/share/virtualenvs/text_recognition-eMREPB2y/lib/python3.9/site-packages/django/views/generic/base.py", line 84, in view
    return self.dispatch(request, *args, **kwargs)
  File "/Users/jairajsahgal/.local/share/virtualenvs/text_recognition-eMREPB2y/lib/python3.9/site-packages/rest_framework/views.py", line 509, in dispatch
    response = self.handle_exception(exc)
  File "/Users/jairajsahgal/.local/share/virtualenvs/text_recognition-eMREPB2y/lib/python3.9/site-packages/rest_framework/views.py", line 469, in handle_exception
    self.raise_uncaught_exception(exc)
  File "/Users/jairajsahgal/.local/share/virtualenvs/text_recognition-eMREPB2y/lib/python3.9/site-packages/rest_framework/views.py", line 480, in raise_uncaught_exception
    raise exc
  File "/Users/jairajsahgal/.local/share/virtualenvs/text_recognition-eMREPB2y/lib/python3.9/site-packages/rest_framework/views.py", line 506, in dispatch
    response = handler(request, *args, **kwargs)
  File "/Users/jairajsahgal/.local/share/virtualenvs/text_recognition-eMREPB2y/lib/python3.9/site-packages/rest_framework/decorators.py", line 50, in handler
    return func(*args, **kwargs)
  File "/Users/jairajsahgal/Documents/django/text_recognition_api/text_recognition/api/views.py", line 66, in login_account
    if serializer.is_valid(raise_exception=True):
  File "/Users/jairajsahgal/.local/share/virtualenvs/text_recognition-eMREPB2y/lib/python3.9/site-packages/rest_framework/serializers.py", line 227, in is_valid
    self._validated_data = self.run_validation(self.initial_data)
  File "/Users/jairajsahgal/.local/share/virtualenvs/text_recognition-eMREPB2y/lib/python3.9/site-packages/rest_framework/serializers.py", line 426, in run_validation
    value = self.to_internal_value(data)
  File "/Users/jairajsahgal/.local/share/virtualenvs/text_recognition-eMREPB2y/lib/python3.9/site-packages/rest_framework/serializers.py", line 479, in to_internal_value
    for field in fields:
  File "/Users/jairajsahgal/.local/share/virtualenvs/text_recognition-eMREPB2y/lib/python3.9/site-packages/rest_framework/serializers.py", line 362, in _writable_fields
    for field in self.fields.values():
  File "/Users/jairajsahgal/.local/share/virtualenvs/text_recognition-eMREPB2y/lib/python3.9/site-packages/django/utils/functional.py", line 49, in __get__
    res = instance.__dict__[self.name] = self.func(instance)
  File "/Users/jairajsahgal/.local/share/virtualenvs/text_recognition-eMREPB2y/lib/python3.9/site-packages/rest_framework/serializers.py", line 356, in fields
    for key, value in self.get_fields().items():
  File "/Users/jairajsahgal/.local/share/virtualenvs/text_recognition-eMREPB2y/lib/python3.9/site-packages/rest_framework/serializers.py", line 1052, in get_fields
    field_names = self.get_field_names(declared_fields, info)
  File "/Users/jairajsahgal/.local/share/virtualenvs/text_recognition-eMREPB2y/lib/python3.9/site-packages/rest_framework/serializers.py", line 1148, in get_field_names
    assert field_name in fields, (
AssertionError: The field 'password' was declared on serializer LoginSerializer, but has not been included in the 'fields' option.
Bad Request: /account/login/
Bad Request: /account/login/
Internal Server Error: /account/login/
Traceback (most recent call last):
  File "/Users/jairajsahgal/.local/share/virtualenvs/text_recognition-eMREPB2y/lib/python3.9/site-packages/django/core/handlers/exception.py", line 55, in inner
    response = get_response(request)
  File "/Users/jairajsahgal/.local/share/virtualenvs/text_recognition-eMREPB2y/lib/python3.9/site-packages/django/core/handlers/base.py", line 197, in _get_response
    response = wrapped_callback(request, *callback_args, **callback_kwargs)
  File "/Users/jairajsahgal/.local/share/virtualenvs/text_recognition-eMREPB2y/lib/python3.9/site-packages/django/views/decorators/csrf.py", line 54, in wrapped_view
    return view_func(*args, **kwargs)
  File "/Users/jairajsahgal/.local/share/virtualenvs/text_recognition-eMREPB2y/lib/python3.9/site-packages/django/views/generic/base.py", line 84, in view
    return self.dispatch(request, *args, **kwargs)
  File "/Users/jairajsahgal/.local/share/virtualenvs/text_recognition-eMREPB2y/lib/python3.9/site-packages/rest_framework/views.py", line 509, in dispatch
    response = self.handle_exception(exc)
  File "/Users/jairajsahgal/.local/share/virtualenvs/text_recognition-eMREPB2y/lib/python3.9/site-packages/rest_framework/views.py", line 469, in handle_exception
    self.raise_uncaught_exception(exc)
  File "/Users/jairajsahgal/.local/share/virtualenvs/text_recognition-eMREPB2y/lib/python3.9/site-packages/rest_framework/views.py", line 480, in raise_uncaught_exception
    raise exc
  File "/Users/jairajsahgal/.local/share/virtualenvs/text_recognition-eMREPB2y/lib/python3.9/site-packages/rest_framework/views.py", line 506, in dispatch
    response = handler(request, *args, **kwargs)
  File "/Users/jairajsahgal/.local/share/virtualenvs/text_recognition-eMREPB2y/lib/python3.9/site-packages/rest_framework/decorators.py", line 50, in handler
    return func(*args, **kwargs)
  File "/Users/jairajsahgal/Documents/django/text_recognition_api/text_recognition/api/views.py", line 66, in login_account
    if serializer.is_valid(raise_exception=True):
  File "/Users/jairajsahgal/.local/share/virtualenvs/text_recognition-eMREPB2y/lib/python3.9/site-packages/rest_framework/serializers.py", line 227, in is_valid
    self._validated_data = self.run_validation(self.initial_data)
  File "/Users/jairajsahgal/.local/share/virtualenvs/text_recognition-eMREPB2y/lib/python3.9/site-packages/rest_framework/serializers.py", line 429, in run_validation
    value = self.validate(value)
  File "/Users/jairajsahgal/Documents/django/text_recognition_api/text_recognition/api/serializers.py", line 40, in validate
    account=account.pop()
AttributeError: 'QuerySet' object has no attribute 'pop'
Internal Server Error: /account/upload_image/
Traceback (most recent call last):
  File "/Users/jairajsahgal/.local/share/virtualenvs/text_recognition-eMREPB2y/lib/python3.9/site-packages/django/db/backends/utils.py", line 89, in _execute
    return self.cursor.execute(sql, params)
  File "/Users/jairajsahgal/.local/share/virtualenvs/text_recognition-eMREPB2y/lib/python3.9/site-packages/django/db/backends/sqlite3/base.py", line 477, in execute
    return Database.Cursor.execute(self, query, params)
sqlite3.IntegrityError: NOT NULL constraint failed: api_picture.account_id

The above exception was the direct cause of the following exception:

Traceback (most recent call last):
  File "/Users/jairajsahgal/.local/share/virtualenvs/text_recognition-eMREPB2y/lib/python3.9/site-packages/django/core/handlers/exception.py", line 55, in inner
    response = get_response(request)
  File "/Users/jairajsahgal/.local/share/virtualenvs/text_recognition-eMREPB2y/lib/python3.9/site-packages/django/core/handlers/base.py", line 197, in _get_response
    response = wrapped_callback(request, *callback_args, **callback_kwargs)
  File "/Users/jairajsahgal/.local/share/virtualenvs/text_recognition-eMREPB2y/lib/python3.9/site-packages/django/views/decorators/csrf.py", line 54, in wrapped_view
    return view_func(*args, **kwargs)
  File "/Users/jairajsahgal/.local/share/virtualenvs/text_recognition-eMREPB2y/lib/python3.9/site-packages/django/views/generic/base.py", line 84, in view
    return self.dispatch(request, *args, **kwargs)
  File "/Users/jairajsahgal/.local/share/virtualenvs/text_recognition-eMREPB2y/lib/python3.9/site-packages/rest_framework/views.py", line 509, in dispatch
    response = self.handle_exception(exc)
  File "/Users/jairajsahgal/.local/share/virtualenvs/text_recognition-eMREPB2y/lib/python3.9/site-packages/rest_framework/views.py", line 469, in handle_exception
    self.raise_uncaught_exception(exc)
  File "/Users/jairajsahgal/.local/share/virtualenvs/text_recognition-eMREPB2y/lib/python3.9/site-packages/rest_framework/views.py", line 480, in raise_uncaught_exception
    raise exc
  File "/Users/jairajsahgal/.local/share/virtualenvs/text_recognition-eMREPB2y/lib/python3.9/site-packages/rest_framework/views.py", line 506, in dispatch
    response = handler(request, *args, **kwargs)
  File "/Users/jairajsahgal/.local/share/virtualenvs/text_recognition-eMREPB2y/lib/python3.9/site-packages/rest_framework/decorators.py", line 50, in handler
    return func(*args, **kwargs)
  File "/Users/jairajsahgal/Documents/django/text_recognition_api/text_recognition/api/views.py", line 105, in uploadImage
    serializer.save()
  File "/Users/jairajsahgal/.local/share/virtualenvs/text_recognition-eMREPB2y/lib/python3.9/site-packages/rest_framework/serializers.py", line 212, in save
    self.instance = self.create(validated_data)
  File "/Users/jairajsahgal/.local/share/virtualenvs/text_recognition-eMREPB2y/lib/python3.9/site-packages/rest_framework/serializers.py", line 962, in create
    instance = ModelClass._default_manager.create(**validated_data)
  File "/Users/jairajsahgal/.local/share/virtualenvs/text_recognition-eMREPB2y/lib/python3.9/site-packages/django/db/models/manager.py", line 85, in manager_method
    return getattr(self.get_queryset(), name)(*args, **kwargs)
  File "/Users/jairajsahgal/.local/share/virtualenvs/text_recognition-eMREPB2y/lib/python3.9/site-packages/django/db/models/query.py", line 514, in create
    obj.save(force_insert=True, using=self.db)
  File "/Users/jairajsahgal/.local/share/virtualenvs/text_recognition-eMREPB2y/lib/python3.9/site-packages/django/db/models/base.py", line 806, in save
    self.save_base(
  File "/Users/jairajsahgal/.local/share/virtualenvs/text_recognition-eMREPB2y/lib/python3.9/site-packages/django/db/models/base.py", line 857, in save_base
    updated = self._save_table(
  File "/Users/jairajsahgal/.local/share/virtualenvs/text_recognition-eMREPB2y/lib/python3.9/site-packages/django/db/models/base.py", line 1000, in _save_table
    results = self._do_insert(
  File "/Users/jairajsahgal/.local/share/virtualenvs/text_recognition-eMREPB2y/lib/python3.9/site-packages/django/db/models/base.py", line 1041, in _do_insert
    return manager._insert(
  File "/Users/jairajsahgal/.local/share/virtualenvs/text_recognition-eMREPB2y/lib/python3.9/site-packages/django/db/models/manager.py", line 85, in manager_method
    return getattr(self.get_queryset(), name)(*args, **kwargs)
  File "/Users/jairajsahgal/.local/share/virtualenvs/text_recognition-eMREPB2y/lib/python3.9/site-packages/django/db/models/query.py", line 1434, in _insert
    return query.get_compiler(using=using).execute_sql(returning_fields)
  File "/Users/jairajsahgal/.local/share/virtualenvs/text_recognition-eMREPB2y/lib/python3.9/site-packages/django/db/models/sql/compiler.py", line 1621, in execute_sql
    cursor.execute(sql, params)
  File "/Users/jairajsahgal/.local/share/virtualenvs/text_recognition-eMREPB2y/lib/python3.9/site-packages/django/db/backends/utils.py", line 103, in execute
    return super().execute(sql, params)
  File "/Users/jairajsahgal/.local/share/virtualenvs/text_recognition-eMREPB2y/lib/python3.9/site-packages/django/db/backends/utils.py", line 67, in execute
    return self._execute_with_wrappers(
  File "/Users/jairajsahgal/.local/share/virtualenvs/text_recognition-eMREPB2y/lib/python3.9/site-packages/django/db/backends/utils.py", line 80, in _execute_with_wrappers
    return executor(sql, params, many, context)
  File "/Users/jairajsahgal/.local/share/virtualenvs/text_recognition-eMREPB2y/lib/python3.9/site-packages/django/db/backends/utils.py", line 89, in _execute
    return self.cursor.execute(sql, params)
  File "/Users/jairajsahgal/.local/share/virtualenvs/text_recognition-eMREPB2y/lib/python3.9/site-packages/django/db/utils.py", line 91, in __exit__
    raise dj_exc_value.with_traceback(traceback) from exc_value
  File "/Users/jairajsahgal/.local/share/virtualenvs/text_recognition-eMREPB2y/lib/python3.9/site-packages/django/db/backends/utils.py", line 89, in _execute
    return self.cursor.execute(sql, params)
  File "/Users/jairajsahgal/.local/share/virtualenvs/text_recognition-eMREPB2y/lib/python3.9/site-packages/django/db/backends/sqlite3/base.py", line 477, in execute
    return Database.Cursor.execute(self, query, params)
django.db.utils.IntegrityError: NOT NULL constraint failed: api_picture.account_id
Internal Server Error: /account/upload_image/
Traceback (most recent call last):
  File "/Users/jairajsahgal/.local/share/virtualenvs/text_recognition-eMREPB2y/lib/python3.9/site-packages/django/db/backends/utils.py", line 89, in _execute
    return self.cursor.execute(sql, params)
  File "/Users/jairajsahgal/.local/share/virtualenvs/text_recognition-eMREPB2y/lib/python3.9/site-packages/django/db/backends/sqlite3/base.py", line 477, in execute
    return Database.Cursor.execute(self, query, params)
sqlite3.IntegrityError: NOT NULL constraint failed: api_picture.account_id

The above exception was the direct cause of the following exception:

Traceback (most recent call last):
  File "/Users/jairajsahgal/.local/share/virtualenvs/text_recognition-eMREPB2y/lib/python3.9/site-packages/django/core/handlers/exception.py", line 55, in inner
    response = get_response(request)
  File "/Users/jairajsahgal/.local/share/virtualenvs/text_recognition-eMREPB2y/lib/python3.9/site-packages/django/core/handlers/base.py", line 197, in _get_response
    response = wrapped_callback(request, *callback_args, **callback_kwargs)
  File "/Users/jairajsahgal/.local/share/virtualenvs/text_recognition-eMREPB2y/lib/python3.9/site-packages/django/views/decorators/csrf.py", line 54, in wrapped_view
    return view_func(*args, **kwargs)
  File "/Users/jairajsahgal/.local/share/virtualenvs/text_recognition-eMREPB2y/lib/python3.9/site-packages/django/views/generic/base.py", line 84, in view
    return self.dispatch(request, *args, **kwargs)
  File "/Users/jairajsahgal/.local/share/virtualenvs/text_recognition-eMREPB2y/lib/python3.9/site-packages/rest_framework/views.py", line 509, in dispatch
    response = self.handle_exception(exc)
  File "/Users/jairajsahgal/.local/share/virtualenvs/text_recognition-eMREPB2y/lib/python3.9/site-packages/rest_framework/views.py", line 469, in handle_exception
    self.raise_uncaught_exception(exc)
  File "/Users/jairajsahgal/.local/share/virtualenvs/text_recognition-eMREPB2y/lib/python3.9/site-packages/rest_framework/views.py", line 480, in raise_uncaught_exception
    raise exc
  File "/Users/jairajsahgal/.local/share/virtualenvs/text_recognition-eMREPB2y/lib/python3.9/site-packages/rest_framework/views.py", line 506, in dispatch
    response = handler(request, *args, **kwargs)
  File "/Users/jairajsahgal/.local/share/virtualenvs/text_recognition-eMREPB2y/lib/python3.9/site-packages/rest_framework/decorators.py", line 50, in handler
    return func(*args, **kwargs)
  File "/Users/jairajsahgal/Documents/django/text_recognition_api/text_recognition/api/views.py", line 105, in uploadImage
    serializer.save()
  File "/Users/jairajsahgal/.local/share/virtualenvs/text_recognition-eMREPB2y/lib/python3.9/site-packages/rest_framework/serializers.py", line 212, in save
    self.instance = self.create(validated_data)
  File "/Users/jairajsahgal/.local/share/virtualenvs/text_recognition-eMREPB2y/lib/python3.9/site-packages/rest_framework/serializers.py", line 962, in create
    instance = ModelClass._default_manager.create(**validated_data)
  File "/Users/jairajsahgal/.local/share/virtualenvs/text_recognition-eMREPB2y/lib/python3.9/site-packages/django/db/models/manager.py", line 85, in manager_method
    return getattr(self.get_queryset(), name)(*args, **kwargs)
  File "/Users/jairajsahgal/.local/share/virtualenvs/text_recognition-eMREPB2y/lib/python3.9/site-packages/django/db/models/query.py", line 514, in create
    obj.save(force_insert=True, using=self.db)
  File "/Users/jairajsahgal/.local/share/virtualenvs/text_recognition-eMREPB2y/lib/python3.9/site-packages/django/db/models/base.py", line 806, in save
    self.save_base(
  File "/Users/jairajsahgal/.local/share/virtualenvs/text_recognition-eMREPB2y/lib/python3.9/site-packages/django/db/models/base.py", line 857, in save_base
    updated = self._save_table(
  File "/Users/jairajsahgal/.local/share/virtualenvs/text_recognition-eMREPB2y/lib/python3.9/site-packages/django/db/models/base.py", line 1000, in _save_table
    results = self._do_insert(
  File "/Users/jairajsahgal/.local/share/virtualenvs/text_recognition-eMREPB2y/lib/python3.9/site-packages/django/db/models/base.py", line 1041, in _do_insert
    return manager._insert(
  File "/Users/jairajsahgal/.local/share/virtualenvs/text_recognition-eMREPB2y/lib/python3.9/site-packages/django/db/models/manager.py", line 85, in manager_method
    return getattr(self.get_queryset(), name)(*args, **kwargs)
  File "/Users/jairajsahgal/.local/share/virtualenvs/text_recognition-eMREPB2y/lib/python3.9/site-packages/django/db/models/query.py", line 1434, in _insert
    return query.get_compiler(using=using).execute_sql(returning_fields)
  File "/Users/jairajsahgal/.local/share/virtualenvs/text_recognition-eMREPB2y/lib/python3.9/site-packages/django/db/models/sql/compiler.py", line 1621, in execute_sql
    cursor.execute(sql, params)
  File "/Users/jairajsahgal/.local/share/virtualenvs/text_recognition-eMREPB2y/lib/python3.9/site-packages/django/db/backends/utils.py", line 103, in execute
    return super().execute(sql, params)
  File "/Users/jairajsahgal/.local/share/virtualenvs/text_recognition-eMREPB2y/lib/python3.9/site-packages/django/db/backends/utils.py", line 67, in execute
    return self._execute_with_wrappers(
  File "/Users/jairajsahgal/.local/share/virtualenvs/text_recognition-eMREPB2y/lib/python3.9/site-packages/django/db/backends/utils.py", line 80, in _execute_with_wrappers
    return executor(sql, params, many, context)
  File "/Users/jairajsahgal/.local/share/virtualenvs/text_recognition-eMREPB2y/lib/python3.9/site-packages/django/db/backends/utils.py", line 89, in _execute
    return self.cursor.execute(sql, params)
  File "/Users/jairajsahgal/.local/share/virtualenvs/text_recognition-eMREPB2y/lib/python3.9/site-packages/django/db/utils.py", line 91, in __exit__
    raise dj_exc_value.with_traceback(traceback) from exc_value
  File "/Users/jairajsahgal/.local/share/virtualenvs/text_recognition-eMREPB2y/lib/python3.9/site-packages/django/db/backends/utils.py", line 89, in _execute
    return self.cursor.execute(sql, params)
  File "/Users/jairajsahgal/.local/share/virtualenvs/text_recognition-eMREPB2y/lib/python3.9/site-packages/django/db/backends/sqlite3/base.py", line 477, in execute
    return Database.Cursor.execute(self, query, params)
django.db.utils.IntegrityError: NOT NULL constraint failed: api_picture.account_id
Internal Server Error: /account/upload_image/
Traceback (most recent call last):
  File "/Users/jairajsahgal/.local/share/virtualenvs/text_recognition-eMREPB2y/lib/python3.9/site-packages/django/core/handlers/exception.py", line 55, in inner
    response = get_response(request)
  File "/Users/jairajsahgal/.local/share/virtualenvs/text_recognition-eMREPB2y/lib/python3.9/site-packages/django/core/handlers/base.py", line 197, in _get_response
    response = wrapped_callback(request, *callback_args, **callback_kwargs)
  File "/Users/jairajsahgal/.local/share/virtualenvs/text_recognition-eMREPB2y/lib/python3.9/site-packages/django/views/decorators/csrf.py", line 54, in wrapped_view
    return view_func(*args, **kwargs)
  File "/Users/jairajsahgal/.local/share/virtualenvs/text_recognition-eMREPB2y/lib/python3.9/site-packages/django/views/generic/base.py", line 84, in view
    return self.dispatch(request, *args, **kwargs)
  File "/Users/jairajsahgal/.local/share/virtualenvs/text_recognition-eMREPB2y/lib/python3.9/site-packages/rest_framework/views.py", line 509, in dispatch
    response = self.handle_exception(exc)
  File "/Users/jairajsahgal/.local/share/virtualenvs/text_recognition-eMREPB2y/lib/python3.9/site-packages/rest_framework/views.py", line 469, in handle_exception
    self.raise_uncaught_exception(exc)
  File "/Users/jairajsahgal/.local/share/virtualenvs/text_recognition-eMREPB2y/lib/python3.9/site-packages/rest_framework/views.py", line 480, in raise_uncaught_exception
    raise exc
  File "/Users/jairajsahgal/.local/share/virtualenvs/text_recognition-eMREPB2y/lib/python3.9/site-packages/rest_framework/views.py", line 506, in dispatch
    response = handler(request, *args, **kwargs)
  File "/Users/jairajsahgal/.local/share/virtualenvs/text_recognition-eMREPB2y/lib/python3.9/site-packages/rest_framework/decorators.py", line 50, in handler
    return func(*args, **kwargs)
  File "/Users/jairajsahgal/Documents/django/text_recognition_api/text_recognition/api/views.py", line 114, in uploadImage
    pictureObject = Picture.object.create(account=accountObject,image=file)
AttributeError: type object 'Picture' has no attribute 'object'
Internal Server Error: /account/upload_image/
Traceback (most recent call last):
  File "/Users/jairajsahgal/.local/share/virtualenvs/text_recognition-eMREPB2y/lib/python3.9/site-packages/django/core/handlers/exception.py", line 55, in inner
    response = get_response(request)
  File "/Users/jairajsahgal/.local/share/virtualenvs/text_recognition-eMREPB2y/lib/python3.9/site-packages/django/core/handlers/base.py", line 220, in _get_response
    response = response.render()
  File "/Users/jairajsahgal/.local/share/virtualenvs/text_recognition-eMREPB2y/lib/python3.9/site-packages/django/template/response.py", line 114, in render
    self.content = self.rendered_content
  File "/Users/jairajsahgal/.local/share/virtualenvs/text_recognition-eMREPB2y/lib/python3.9/site-packages/rest_framework/response.py", line 70, in rendered_content
    ret = renderer.render(self.data, accepted_media_type, context)
  File "/Users/jairajsahgal/.local/share/virtualenvs/text_recognition-eMREPB2y/lib/python3.9/site-packages/rest_framework/renderers.py", line 100, in render
    ret = json.dumps(
  File "/Users/jairajsahgal/.local/share/virtualenvs/text_recognition-eMREPB2y/lib/python3.9/site-packages/rest_framework/utils/json.py", line 25, in dumps
    return json.dumps(*args, **kwargs)
  File "/opt/homebrew/Cellar/python@3.9/3.9.12/Frameworks/Python.framework/Versions/3.9/lib/python3.9/json/__init__.py", line 234, in dumps
    return cls(
  File "/opt/homebrew/Cellar/python@3.9/3.9.12/Frameworks/Python.framework/Versions/3.9/lib/python3.9/json/encoder.py", line 199, in encode
    chunks = self.iterencode(o, _one_shot=True)
  File "/opt/homebrew/Cellar/python@3.9/3.9.12/Frameworks/Python.framework/Versions/3.9/lib/python3.9/json/encoder.py", line 257, in iterencode
    return _iterencode(o, 0)
  File "/Users/jairajsahgal/.local/share/virtualenvs/text_recognition-eMREPB2y/lib/python3.9/site-packages/rest_framework/utils/encoders.py", line 50, in default
    return obj.decode()
UnicodeDecodeError: 'utf-8' codec can't decode byte 0x89 in position 0: invalid start byte
Unauthorized: /account/upload_image/
Not Found: /favicon.ico
Unauthorized: /account/upload_image/
Unauthorized: /account/upload_image/
Unauthorized: /account/picture-list/
Unauthorized: /account/upload_image/
Unauthorized: /account/upload_image/
Internal Server Error: /account/upload_image/
Traceback (most recent call last):
  File "/Users/jairajsahgal/miniforge3/envs/cv/lib/python3.8/site-packages/django/core/handlers/exception.py", line 55, in inner
    response = get_response(request)
  File "/Users/jairajsahgal/miniforge3/envs/cv/lib/python3.8/site-packages/django/core/handlers/base.py", line 197, in _get_response
    response = wrapped_callback(request, *callback_args, **callback_kwargs)
  File "/Users/jairajsahgal/miniforge3/envs/cv/lib/python3.8/site-packages/django/views/decorators/csrf.py", line 54, in wrapped_view
    return view_func(*args, **kwargs)
  File "/Users/jairajsahgal/miniforge3/envs/cv/lib/python3.8/site-packages/django/views/generic/base.py", line 84, in view
    return self.dispatch(request, *args, **kwargs)
  File "/Users/jairajsahgal/miniforge3/envs/cv/lib/python3.8/site-packages/rest_framework/views.py", line 509, in dispatch
    response = self.handle_exception(exc)
  File "/Users/jairajsahgal/miniforge3/envs/cv/lib/python3.8/site-packages/rest_framework/views.py", line 469, in handle_exception
    self.raise_uncaught_exception(exc)
  File "/Users/jairajsahgal/miniforge3/envs/cv/lib/python3.8/site-packages/rest_framework/views.py", line 480, in raise_uncaught_exception
    raise exc
  File "/Users/jairajsahgal/miniforge3/envs/cv/lib/python3.8/site-packages/rest_framework/views.py", line 506, in dispatch
    response = handler(request, *args, **kwargs)
  File "/Users/jairajsahgal/miniforge3/envs/cv/lib/python3.8/site-packages/rest_framework/decorators.py", line 50, in handler
    return func(*args, **kwargs)
  File "/Users/jairajsahgal/Documents/django/text_recognition_api/text_recognition/api/views.py", line 123, in uploadImage
    "image": pictureObject.image.url,
  File "/Users/jairajsahgal/miniforge3/envs/cv/lib/python3.8/site-packages/django/db/models/fields/files.py", line 65, in url
    self._require_file()
  File "/Users/jairajsahgal/miniforge3/envs/cv/lib/python3.8/site-packages/django/db/models/fields/files.py", line 40, in _require_file
    raise ValueError(
ValueError: The 'image' attribute has no file associated with it.
Internal Server Error: /account/upload_image/
Traceback (most recent call last):
  File "/Users/jairajsahgal/miniforge3/envs/cv/lib/python3.8/site-packages/django/core/handlers/exception.py", line 55, in inner
    response = get_response(request)
  File "/Users/jairajsahgal/miniforge3/envs/cv/lib/python3.8/site-packages/django/core/handlers/base.py", line 197, in _get_response
    response = wrapped_callback(request, *callback_args, **callback_kwargs)
  File "/Users/jairajsahgal/miniforge3/envs/cv/lib/python3.8/site-packages/django/views/decorators/csrf.py", line 54, in wrapped_view
    return view_func(*args, **kwargs)
  File "/Users/jairajsahgal/miniforge3/envs/cv/lib/python3.8/site-packages/django/views/generic/base.py", line 84, in view
    return self.dispatch(request, *args, **kwargs)
  File "/Users/jairajsahgal/miniforge3/envs/cv/lib/python3.8/site-packages/rest_framework/views.py", line 509, in dispatch
    response = self.handle_exception(exc)
  File "/Users/jairajsahgal/miniforge3/envs/cv/lib/python3.8/site-packages/rest_framework/views.py", line 469, in handle_exception
    self.raise_uncaught_exception(exc)
  File "/Users/jairajsahgal/miniforge3/envs/cv/lib/python3.8/site-packages/rest_framework/views.py", line 480, in raise_uncaught_exception
    raise exc
  File "/Users/jairajsahgal/miniforge3/envs/cv/lib/python3.8/site-packages/rest_framework/views.py", line 506, in dispatch
    response = handler(request, *args, **kwargs)
  File "/Users/jairajsahgal/miniforge3/envs/cv/lib/python3.8/site-packages/rest_framework/decorators.py", line 50, in handler
    return func(*args, **kwargs)
  File "/Users/jairajsahgal/Documents/django/text_recognition_api/text_recognition/api/views.py", line 125, in uploadImage
    "image": pictureObject.image.url,
  File "/Users/jairajsahgal/miniforge3/envs/cv/lib/python3.8/site-packages/django/db/models/fields/files.py", line 65, in url
    self._require_file()
  File "/Users/jairajsahgal/miniforge3/envs/cv/lib/python3.8/site-packages/django/db/models/fields/files.py", line 40, in _require_file
    raise ValueError(
ValueError: The 'image' attribute has no file associated with it.
Internal Server Error: /account/upload_image/
Traceback (most recent call last):
  File "/Users/jairajsahgal/miniforge3/envs/cv/lib/python3.8/site-packages/django/core/handlers/exception.py", line 55, in inner
    response = get_response(request)
  File "/Users/jairajsahgal/miniforge3/envs/cv/lib/python3.8/site-packages/django/core/handlers/base.py", line 197, in _get_response
    response = wrapped_callback(request, *callback_args, **callback_kwargs)
  File "/Users/jairajsahgal/miniforge3/envs/cv/lib/python3.8/site-packages/django/views/decorators/csrf.py", line 54, in wrapped_view
    return view_func(*args, **kwargs)
  File "/Users/jairajsahgal/miniforge3/envs/cv/lib/python3.8/site-packages/django/views/generic/base.py", line 84, in view
    return self.dispatch(request, *args, **kwargs)
  File "/Users/jairajsahgal/miniforge3/envs/cv/lib/python3.8/site-packages/rest_framework/views.py", line 509, in dispatch
    response = self.handle_exception(exc)
  File "/Users/jairajsahgal/miniforge3/envs/cv/lib/python3.8/site-packages/rest_framework/views.py", line 469, in handle_exception
    self.raise_uncaught_exception(exc)
  File "/Users/jairajsahgal/miniforge3/envs/cv/lib/python3.8/site-packages/rest_framework/views.py", line 480, in raise_uncaught_exception
    raise exc
  File "/Users/jairajsahgal/miniforge3/envs/cv/lib/python3.8/site-packages/rest_framework/views.py", line 506, in dispatch
    response = handler(request, *args, **kwargs)
  File "/Users/jairajsahgal/miniforge3/envs/cv/lib/python3.8/site-packages/rest_framework/decorators.py", line 50, in handler
    return func(*args, **kwargs)
  File "/Users/jairajsahgal/Documents/django/text_recognition_api/text_recognition/api/views.py", line 125, in uploadImage
    "image": pictureObject.image.url,
  File "/Users/jairajsahgal/miniforge3/envs/cv/lib/python3.8/site-packages/django/db/models/fields/files.py", line 65, in url
    self._require_file()
  File "/Users/jairajsahgal/miniforge3/envs/cv/lib/python3.8/site-packages/django/db/models/fields/files.py", line 40, in _require_file
    raise ValueError(
ValueError: The 'image' attribute has no file associated with it.
Internal Server Error: /account/upload_image/
Traceback (most recent call last):
  File "/Users/jairajsahgal/miniforge3/envs/cv/lib/python3.8/site-packages/django/core/handlers/exception.py", line 55, in inner
    response = get_response(request)
  File "/Users/jairajsahgal/miniforge3/envs/cv/lib/python3.8/site-packages/django/core/handlers/base.py", line 197, in _get_response
    response = wrapped_callback(request, *callback_args, **callback_kwargs)
  File "/Users/jairajsahgal/miniforge3/envs/cv/lib/python3.8/site-packages/django/views/decorators/csrf.py", line 54, in wrapped_view
    return view_func(*args, **kwargs)
  File "/Users/jairajsahgal/miniforge3/envs/cv/lib/python3.8/site-packages/django/views/generic/base.py", line 84, in view
    return self.dispatch(request, *args, **kwargs)
  File "/Users/jairajsahgal/miniforge3/envs/cv/lib/python3.8/site-packages/rest_framework/views.py", line 509, in dispatch
    response = self.handle_exception(exc)
  File "/Users/jairajsahgal/miniforge3/envs/cv/lib/python3.8/site-packages/rest_framework/views.py", line 469, in handle_exception
    self.raise_uncaught_exception(exc)
  File "/Users/jairajsahgal/miniforge3/envs/cv/lib/python3.8/site-packages/rest_framework/views.py", line 480, in raise_uncaught_exception
    raise exc
  File "/Users/jairajsahgal/miniforge3/envs/cv/lib/python3.8/site-packages/rest_framework/views.py", line 506, in dispatch
    response = handler(request, *args, **kwargs)
  File "/Users/jairajsahgal/miniforge3/envs/cv/lib/python3.8/site-packages/rest_framework/decorators.py", line 50, in handler
    return func(*args, **kwargs)
  File "/Users/jairajsahgal/Documents/django/text_recognition_api/text_recognition/api/views.py", line 126, in uploadImage
    "image": pictureObject.image.url,
  File "/Users/jairajsahgal/miniforge3/envs/cv/lib/python3.8/site-packages/django/db/models/fields/files.py", line 65, in url
    self._require_file()
  File "/Users/jairajsahgal/miniforge3/envs/cv/lib/python3.8/site-packages/django/db/models/fields/files.py", line 40, in _require_file
    raise ValueError(
ValueError: The 'image' attribute has no file associated with it.
Internal Server Error: /account/upload_image/
Traceback (most recent call last):
  File "/Users/jairajsahgal/miniforge3/envs/cv/lib/python3.8/site-packages/django/core/handlers/exception.py", line 55, in inner
    response = get_response(request)
  File "/Users/jairajsahgal/miniforge3/envs/cv/lib/python3.8/site-packages/django/core/handlers/base.py", line 197, in _get_response
    response = wrapped_callback(request, *callback_args, **callback_kwargs)
  File "/Users/jairajsahgal/miniforge3/envs/cv/lib/python3.8/site-packages/django/views/decorators/csrf.py", line 54, in wrapped_view
    return view_func(*args, **kwargs)
  File "/Users/jairajsahgal/miniforge3/envs/cv/lib/python3.8/site-packages/django/views/generic/base.py", line 84, in view
    return self.dispatch(request, *args, **kwargs)
  File "/Users/jairajsahgal/miniforge3/envs/cv/lib/python3.8/site-packages/rest_framework/views.py", line 509, in dispatch
    response = self.handle_exception(exc)
  File "/Users/jairajsahgal/miniforge3/envs/cv/lib/python3.8/site-packages/rest_framework/views.py", line 469, in handle_exception
    self.raise_uncaught_exception(exc)
  File "/Users/jairajsahgal/miniforge3/envs/cv/lib/python3.8/site-packages/rest_framework/views.py", line 480, in raise_uncaught_exception
    raise exc
  File "/Users/jairajsahgal/miniforge3/envs/cv/lib/python3.8/site-packages/rest_framework/views.py", line 506, in dispatch
    response = handler(request, *args, **kwargs)
  File "/Users/jairajsahgal/miniforge3/envs/cv/lib/python3.8/site-packages/rest_framework/decorators.py", line 50, in handler
    return func(*args, **kwargs)
  File "/Users/jairajsahgal/Documents/django/text_recognition_api/text_recognition/api/views.py", line 127, in uploadImage
    "image": pictureObject.image.url,
  File "/Users/jairajsahgal/miniforge3/envs/cv/lib/python3.8/site-packages/django/db/models/fields/files.py", line 65, in url
    self._require_file()
  File "/Users/jairajsahgal/miniforge3/envs/cv/lib/python3.8/site-packages/django/db/models/fields/files.py", line 40, in _require_file
    raise ValueError(
ValueError: The 'image' attribute has no file associated with it.
Internal Server Error: /account/upload_image/
Traceback (most recent call last):
  File "/Users/jairajsahgal/miniforge3/envs/cv/lib/python3.8/site-packages/django/core/handlers/exception.py", line 55, in inner
    response = get_response(request)
  File "/Users/jairajsahgal/miniforge3/envs/cv/lib/python3.8/site-packages/django/core/handlers/base.py", line 197, in _get_response
    response = wrapped_callback(request, *callback_args, **callback_kwargs)
  File "/Users/jairajsahgal/miniforge3/envs/cv/lib/python3.8/site-packages/django/views/decorators/csrf.py", line 54, in wrapped_view
    return view_func(*args, **kwargs)
  File "/Users/jairajsahgal/miniforge3/envs/cv/lib/python3.8/site-packages/django/views/generic/base.py", line 84, in view
    return self.dispatch(request, *args, **kwargs)
  File "/Users/jairajsahgal/miniforge3/envs/cv/lib/python3.8/site-packages/rest_framework/views.py", line 509, in dispatch
    response = self.handle_exception(exc)
  File "/Users/jairajsahgal/miniforge3/envs/cv/lib/python3.8/site-packages/rest_framework/views.py", line 469, in handle_exception
    self.raise_uncaught_exception(exc)
  File "/Users/jairajsahgal/miniforge3/envs/cv/lib/python3.8/site-packages/rest_framework/views.py", line 480, in raise_uncaught_exception
    raise exc
  File "/Users/jairajsahgal/miniforge3/envs/cv/lib/python3.8/site-packages/rest_framework/views.py", line 506, in dispatch
    response = handler(request, *args, **kwargs)
  File "/Users/jairajsahgal/miniforge3/envs/cv/lib/python3.8/site-packages/rest_framework/decorators.py", line 50, in handler
    return func(*args, **kwargs)
  File "/Users/jairajsahgal/Documents/django/text_recognition_api/text_recognition/api/views.py", line 108, in uploadImage
    if serializer.is_valid():
  File "/Users/jairajsahgal/miniforge3/envs/cv/lib/python3.8/site-packages/rest_framework/serializers.py", line 227, in is_valid
    self._validated_data = self.run_validation(self.initial_data)
  File "/Users/jairajsahgal/miniforge3/envs/cv/lib/python3.8/site-packages/rest_framework/serializers.py", line 429, in run_validation
    value = self.validate(value)
  File "/Users/jairajsahgal/Documents/django/text_recognition_api/text_recognition/api/serializers.py", line 24, in validate
    logger.info(self.context.get('request').user.username)
AttributeError: 'NoneType' object has no attribute 'user'
Internal Server Error: /account/picture-ocr/
Traceback (most recent call last):
  File "/Users/jairajsahgal/miniforge3/envs/cv/lib/python3.8/site-packages/django/core/handlers/exception.py", line 55, in inner
    response = get_response(request)
  File "/Users/jairajsahgal/miniforge3/envs/cv/lib/python3.8/site-packages/django/core/handlers/base.py", line 197, in _get_response
    response = wrapped_callback(request, *callback_args, **callback_kwargs)
  File "/Users/jairajsahgal/miniforge3/envs/cv/lib/python3.8/site-packages/django/views/decorators/csrf.py", line 54, in wrapped_view
    return view_func(*args, **kwargs)
  File "/Users/jairajsahgal/miniforge3/envs/cv/lib/python3.8/site-packages/django/views/generic/base.py", line 84, in view
    return self.dispatch(request, *args, **kwargs)
  File "/Users/jairajsahgal/miniforge3/envs/cv/lib/python3.8/site-packages/rest_framework/views.py", line 509, in dispatch
    response = self.handle_exception(exc)
  File "/Users/jairajsahgal/miniforge3/envs/cv/lib/python3.8/site-packages/rest_framework/views.py", line 469, in handle_exception
    self.raise_uncaught_exception(exc)
  File "/Users/jairajsahgal/miniforge3/envs/cv/lib/python3.8/site-packages/rest_framework/views.py", line 480, in raise_uncaught_exception
    raise exc
  File "/Users/jairajsahgal/miniforge3/envs/cv/lib/python3.8/site-packages/rest_framework/views.py", line 506, in dispatch
    response = handler(request, *args, **kwargs)
  File "/Users/jairajsahgal/miniforge3/envs/cv/lib/python3.8/site-packages/rest_framework/decorators.py", line 50, in handler
    return func(*args, **kwargs)
  File "/Users/jairajsahgal/Documents/django/text_recognition_api/text_recognition/api/views.py", line 172, in get_text_from_image
    img = cv2.cvtColor(img, cv2.COLOR_BGR2GRAY)
cv2.error: OpenCV(4.5.3) /Users/runner/miniforge3/conda-bld/libopencv_1633800949369/work/modules/imgproc/src/color.cpp:182: error: (-215:Assertion failed) !_src.empty() in function 'cvtColor'

Internal Server Error: /account/picture-ocr/
Traceback (most recent call last):
  File "/Users/jairajsahgal/miniforge3/envs/cv/lib/python3.8/site-packages/django/core/handlers/exception.py", line 55, in inner
    response = get_response(request)
  File "/Users/jairajsahgal/miniforge3/envs/cv/lib/python3.8/site-packages/django/core/handlers/base.py", line 197, in _get_response
    response = wrapped_callback(request, *callback_args, **callback_kwargs)
  File "/Users/jairajsahgal/miniforge3/envs/cv/lib/python3.8/site-packages/django/views/decorators/csrf.py", line 54, in wrapped_view
    return view_func(*args, **kwargs)
  File "/Users/jairajsahgal/miniforge3/envs/cv/lib/python3.8/site-packages/django/views/generic/base.py", line 84, in view
    return self.dispatch(request, *args, **kwargs)
  File "/Users/jairajsahgal/miniforge3/envs/cv/lib/python3.8/site-packages/rest_framework/views.py", line 509, in dispatch
    response = self.handle_exception(exc)
  File "/Users/jairajsahgal/miniforge3/envs/cv/lib/python3.8/site-packages/rest_framework/views.py", line 469, in handle_exception
    self.raise_uncaught_exception(exc)
  File "/Users/jairajsahgal/miniforge3/envs/cv/lib/python3.8/site-packages/rest_framework/views.py", line 480, in raise_uncaught_exception
    raise exc
  File "/Users/jairajsahgal/miniforge3/envs/cv/lib/python3.8/site-packages/rest_framework/views.py", line 506, in dispatch
    response = handler(request, *args, **kwargs)
  File "/Users/jairajsahgal/miniforge3/envs/cv/lib/python3.8/site-packages/rest_framework/decorators.py", line 50, in handler
    return func(*args, **kwargs)
  File "/Users/jairajsahgal/Documents/django/text_recognition_api/text_recognition/api/views.py", line 169, in get_text_from_image
    img = cv2.imread(pictureObject.image)
TypeError: Can't convert object of type 'ImageFieldFile' to 'str' for 'filename'
Internal Server Error: /account/picture-ocr/
Traceback (most recent call last):
  File "/Users/jairajsahgal/miniforge3/envs/cv/lib/python3.8/site-packages/django/core/handlers/exception.py", line 55, in inner
    response = get_response(request)
  File "/Users/jairajsahgal/miniforge3/envs/cv/lib/python3.8/site-packages/django/core/handlers/base.py", line 197, in _get_response
    response = wrapped_callback(request, *callback_args, **callback_kwargs)
  File "/Users/jairajsahgal/miniforge3/envs/cv/lib/python3.8/site-packages/django/views/decorators/csrf.py", line 54, in wrapped_view
    return view_func(*args, **kwargs)
  File "/Users/jairajsahgal/miniforge3/envs/cv/lib/python3.8/site-packages/django/views/generic/base.py", line 84, in view
    return self.dispatch(request, *args, **kwargs)
  File "/Users/jairajsahgal/miniforge3/envs/cv/lib/python3.8/site-packages/rest_framework/views.py", line 509, in dispatch
    response = self.handle_exception(exc)
  File "/Users/jairajsahgal/miniforge3/envs/cv/lib/python3.8/site-packages/rest_framework/views.py", line 469, in handle_exception
    self.raise_uncaught_exception(exc)
  File "/Users/jairajsahgal/miniforge3/envs/cv/lib/python3.8/site-packages/rest_framework/views.py", line 480, in raise_uncaught_exception
    raise exc
  File "/Users/jairajsahgal/miniforge3/envs/cv/lib/python3.8/site-packages/rest_framework/views.py", line 506, in dispatch
    response = handler(request, *args, **kwargs)
  File "/Users/jairajsahgal/miniforge3/envs/cv/lib/python3.8/site-packages/rest_framework/decorators.py", line 50, in handler
    return func(*args, **kwargs)
  File "/Users/jairajsahgal/Documents/django/text_recognition_api/text_recognition/api/views.py", line 172, in get_text_from_image
    img = cv2.cvtColor(img, cv2.COLOR_BGR2GRAY)
cv2.error: OpenCV(4.5.3) /Users/runner/miniforge3/conda-bld/libopencv_1633800949369/work/modules/imgproc/src/color.cpp:182: error: (-215:Assertion failed) !_src.empty() in function 'cvtColor'

Internal Server Error: /account/picture-ocr/
Traceback (most recent call last):
  File "/Users/jairajsahgal/miniforge3/envs/cv/lib/python3.8/site-packages/django/core/handlers/exception.py", line 55, in inner
    response = get_response(request)
  File "/Users/jairajsahgal/miniforge3/envs/cv/lib/python3.8/site-packages/django/core/handlers/base.py", line 197, in _get_response
    response = wrapped_callback(request, *callback_args, **callback_kwargs)
  File "/Users/jairajsahgal/miniforge3/envs/cv/lib/python3.8/site-packages/django/views/decorators/csrf.py", line 54, in wrapped_view
    return view_func(*args, **kwargs)
  File "/Users/jairajsahgal/miniforge3/envs/cv/lib/python3.8/site-packages/django/views/generic/base.py", line 84, in view
    return self.dispatch(request, *args, **kwargs)
  File "/Users/jairajsahgal/miniforge3/envs/cv/lib/python3.8/site-packages/rest_framework/views.py", line 509, in dispatch
    response = self.handle_exception(exc)
  File "/Users/jairajsahgal/miniforge3/envs/cv/lib/python3.8/site-packages/rest_framework/views.py", line 469, in handle_exception
    self.raise_uncaught_exception(exc)
  File "/Users/jairajsahgal/miniforge3/envs/cv/lib/python3.8/site-packages/rest_framework/views.py", line 480, in raise_uncaught_exception
    raise exc
  File "/Users/jairajsahgal/miniforge3/envs/cv/lib/python3.8/site-packages/rest_framework/views.py", line 506, in dispatch
    response = handler(request, *args, **kwargs)
  File "/Users/jairajsahgal/miniforge3/envs/cv/lib/python3.8/site-packages/rest_framework/decorators.py", line 50, in handler
    return func(*args, **kwargs)
  File "/Users/jairajsahgal/Documents/django/text_recognition_api/text_recognition/api/views.py", line 171, in get_text_from_image
    logger.info(img.shape)
AttributeError: 'NoneType' object has no attribute 'shape'
Internal Server Error: /account/picture-ocr/
Traceback (most recent call last):
  File "/Users/jairajsahgal/miniforge3/envs/cv/lib/python3.8/site-packages/django/core/handlers/exception.py", line 55, in inner
    response = get_response(request)
  File "/Users/jairajsahgal/miniforge3/envs/cv/lib/python3.8/site-packages/django/core/handlers/base.py", line 197, in _get_response
    response = wrapped_callback(request, *callback_args, **callback_kwargs)
  File "/Users/jairajsahgal/miniforge3/envs/cv/lib/python3.8/site-packages/django/views/decorators/csrf.py", line 54, in wrapped_view
    return view_func(*args, **kwargs)
  File "/Users/jairajsahgal/miniforge3/envs/cv/lib/python3.8/site-packages/django/views/generic/base.py", line 84, in view
    return self.dispatch(request, *args, **kwargs)
  File "/Users/jairajsahgal/miniforge3/envs/cv/lib/python3.8/site-packages/rest_framework/views.py", line 509, in dispatch
    response = self.handle_exception(exc)
  File "/Users/jairajsahgal/miniforge3/envs/cv/lib/python3.8/site-packages/rest_framework/views.py", line 469, in handle_exception
    self.raise_uncaught_exception(exc)
  File "/Users/jairajsahgal/miniforge3/envs/cv/lib/python3.8/site-packages/rest_framework/views.py", line 480, in raise_uncaught_exception
    raise exc
  File "/Users/jairajsahgal/miniforge3/envs/cv/lib/python3.8/site-packages/rest_framework/views.py", line 506, in dispatch
    response = handler(request, *args, **kwargs)
  File "/Users/jairajsahgal/miniforge3/envs/cv/lib/python3.8/site-packages/rest_framework/decorators.py", line 50, in handler
    return func(*args, **kwargs)
  File "/Users/jairajsahgal/Documents/django/text_recognition_api/text_recognition/api/views.py", line 174, in get_text_from_image
    img_path = os.join(value,img_path)
AttributeError: module 'os' has no attribute 'join'
Internal Server Error: /account/picture-ocr/
Traceback (most recent call last):
  File "/Users/jairajsahgal/miniforge3/envs/cv/lib/python3.8/site-packages/django/core/handlers/exception.py", line 55, in inner
    response = get_response(request)
  File "/Users/jairajsahgal/miniforge3/envs/cv/lib/python3.8/site-packages/django/core/handlers/base.py", line 197, in _get_response
    response = wrapped_callback(request, *callback_args, **callback_kwargs)
  File "/Users/jairajsahgal/miniforge3/envs/cv/lib/python3.8/site-packages/django/views/decorators/csrf.py", line 54, in wrapped_view
    return view_func(*args, **kwargs)
  File "/Users/jairajsahgal/miniforge3/envs/cv/lib/python3.8/site-packages/django/views/generic/base.py", line 84, in view
    return self.dispatch(request, *args, **kwargs)
  File "/Users/jairajsahgal/miniforge3/envs/cv/lib/python3.8/site-packages/rest_framework/views.py", line 509, in dispatch
    response = self.handle_exception(exc)
  File "/Users/jairajsahgal/miniforge3/envs/cv/lib/python3.8/site-packages/rest_framework/views.py", line 469, in handle_exception
    self.raise_uncaught_exception(exc)
  File "/Users/jairajsahgal/miniforge3/envs/cv/lib/python3.8/site-packages/rest_framework/views.py", line 480, in raise_uncaught_exception
    raise exc
  File "/Users/jairajsahgal/miniforge3/envs/cv/lib/python3.8/site-packages/rest_framework/views.py", line 506, in dispatch
    response = handler(request, *args, **kwargs)
  File "/Users/jairajsahgal/miniforge3/envs/cv/lib/python3.8/site-packages/rest_framework/decorators.py", line 50, in handler
    return func(*args, **kwargs)
  File "/Users/jairajsahgal/Documents/django/text_recognition_api/text_recognition/api/views.py", line 176, in get_text_from_image
    logger.info(img.shape)
AttributeError: 'NoneType' object has no attribute 'shape'
Internal Server Error: /account/picture-ocr/
Traceback (most recent call last):
  File "/Users/jairajsahgal/miniforge3/envs/cv/lib/python3.8/site-packages/django/core/handlers/exception.py", line 55, in inner
    response = get_response(request)
  File "/Users/jairajsahgal/miniforge3/envs/cv/lib/python3.8/site-packages/django/core/handlers/base.py", line 197, in _get_response
    response = wrapped_callback(request, *callback_args, **callback_kwargs)
  File "/Users/jairajsahgal/miniforge3/envs/cv/lib/python3.8/site-packages/django/views/decorators/csrf.py", line 54, in wrapped_view
    return view_func(*args, **kwargs)
  File "/Users/jairajsahgal/miniforge3/envs/cv/lib/python3.8/site-packages/django/views/generic/base.py", line 84, in view
    return self.dispatch(request, *args, **kwargs)
  File "/Users/jairajsahgal/miniforge3/envs/cv/lib/python3.8/site-packages/rest_framework/views.py", line 509, in dispatch
    response = self.handle_exception(exc)
  File "/Users/jairajsahgal/miniforge3/envs/cv/lib/python3.8/site-packages/rest_framework/views.py", line 469, in handle_exception
    self.raise_uncaught_exception(exc)
  File "/Users/jairajsahgal/miniforge3/envs/cv/lib/python3.8/site-packages/rest_framework/views.py", line 480, in raise_uncaught_exception
    raise exc
  File "/Users/jairajsahgal/miniforge3/envs/cv/lib/python3.8/site-packages/rest_framework/views.py", line 506, in dispatch
    response = handler(request, *args, **kwargs)
  File "/Users/jairajsahgal/miniforge3/envs/cv/lib/python3.8/site-packages/rest_framework/decorators.py", line 50, in handler
    return func(*args, **kwargs)
  File "/Users/jairajsahgal/Documents/django/text_recognition_api/text_recognition/api/views.py", line 180, in get_text_from_image
    img = cv2.cvtColor(img, cv2.COLOR_BGR2GRAY)
cv2.error: OpenCV(4.5.3) /Users/runner/miniforge3/conda-bld/libopencv_1633800949369/work/modules/imgproc/src/color.cpp:182: error: (-215:Assertion failed) !_src.empty() in function 'cvtColor'

Internal Server Error: /account/picture-ocr/
Traceback (most recent call last):
  File "/Users/jairajsahgal/miniforge3/envs/cv/lib/python3.8/site-packages/django/core/handlers/exception.py", line 55, in inner
    response = get_response(request)
  File "/Users/jairajsahgal/miniforge3/envs/cv/lib/python3.8/site-packages/django/core/handlers/base.py", line 197, in _get_response
    response = wrapped_callback(request, *callback_args, **callback_kwargs)
  File "/Users/jairajsahgal/miniforge3/envs/cv/lib/python3.8/site-packages/django/views/decorators/csrf.py", line 54, in wrapped_view
    return view_func(*args, **kwargs)
  File "/Users/jairajsahgal/miniforge3/envs/cv/lib/python3.8/site-packages/django/views/generic/base.py", line 84, in view
    return self.dispatch(request, *args, **kwargs)
  File "/Users/jairajsahgal/miniforge3/envs/cv/lib/python3.8/site-packages/rest_framework/views.py", line 509, in dispatch
    response = self.handle_exception(exc)
  File "/Users/jairajsahgal/miniforge3/envs/cv/lib/python3.8/site-packages/rest_framework/views.py", line 469, in handle_exception
    self.raise_uncaught_exception(exc)
  File "/Users/jairajsahgal/miniforge3/envs/cv/lib/python3.8/site-packages/rest_framework/views.py", line 480, in raise_uncaught_exception
    raise exc
  File "/Users/jairajsahgal/miniforge3/envs/cv/lib/python3.8/site-packages/rest_framework/views.py", line 506, in dispatch
    response = handler(request, *args, **kwargs)
  File "/Users/jairajsahgal/miniforge3/envs/cv/lib/python3.8/site-packages/rest_framework/decorators.py", line 50, in handler
    return func(*args, **kwargs)
  File "/Users/jairajsahgal/Documents/django/text_recognition_api/text_recognition/api/views.py", line 177, in get_text_from_image
    img = cv2.cvtColor(img, cv2.COLOR_BGR2GRAY)
cv2.error: OpenCV(4.5.3) /Users/runner/miniforge3/conda-bld/libopencv_1633800949369/work/modules/imgproc/src/color.cpp:182: error: (-215:Assertion failed) !_src.empty() in function 'cvtColor'

Internal Server Error: /account/picture-ocr/
Traceback (most recent call last):
  File "/Users/jairajsahgal/miniforge3/envs/cv/lib/python3.8/site-packages/django/core/handlers/exception.py", line 55, in inner
    response = get_response(request)
  File "/Users/jairajsahgal/miniforge3/envs/cv/lib/python3.8/site-packages/django/core/handlers/base.py", line 197, in _get_response
    response = wrapped_callback(request, *callback_args, **callback_kwargs)
  File "/Users/jairajsahgal/miniforge3/envs/cv/lib/python3.8/site-packages/django/views/decorators/csrf.py", line 54, in wrapped_view
    return view_func(*args, **kwargs)
  File "/Users/jairajsahgal/miniforge3/envs/cv/lib/python3.8/site-packages/django/views/generic/base.py", line 84, in view
    return self.dispatch(request, *args, **kwargs)
  File "/Users/jairajsahgal/miniforge3/envs/cv/lib/python3.8/site-packages/rest_framework/views.py", line 509, in dispatch
    response = self.handle_exception(exc)
  File "/Users/jairajsahgal/miniforge3/envs/cv/lib/python3.8/site-packages/rest_framework/views.py", line 469, in handle_exception
    self.raise_uncaught_exception(exc)
  File "/Users/jairajsahgal/miniforge3/envs/cv/lib/python3.8/site-packages/rest_framework/views.py", line 480, in raise_uncaught_exception
    raise exc
  File "/Users/jairajsahgal/miniforge3/envs/cv/lib/python3.8/site-packages/rest_framework/views.py", line 506, in dispatch
    response = handler(request, *args, **kwargs)
  File "/Users/jairajsahgal/miniforge3/envs/cv/lib/python3.8/site-packages/rest_framework/decorators.py", line 50, in handler
    return func(*args, **kwargs)
  File "/Users/jairajsahgal/Documents/django/text_recognition_api/text_recognition/api/views.py", line 177, in get_text_from_image
    img = cv2.cvtColor(img, cv2.COLOR_BGR2GRAY)
cv2.error: OpenCV(4.5.3) /Users/runner/miniforge3/conda-bld/libopencv_1633800949369/work/modules/imgproc/src/color.cpp:182: error: (-215:Assertion failed) !_src.empty() in function 'cvtColor'

Internal Server Error: /account/picture-ocr/
Traceback (most recent call last):
  File "/Users/jairajsahgal/miniforge3/envs/cv/lib/python3.8/site-packages/django/core/handlers/exception.py", line 55, in inner
    response = get_response(request)
  File "/Users/jairajsahgal/miniforge3/envs/cv/lib/python3.8/site-packages/django/core/handlers/base.py", line 197, in _get_response
    response = wrapped_callback(request, *callback_args, **callback_kwargs)
  File "/Users/jairajsahgal/miniforge3/envs/cv/lib/python3.8/site-packages/django/views/decorators/csrf.py", line 54, in wrapped_view
    return view_func(*args, **kwargs)
  File "/Users/jairajsahgal/miniforge3/envs/cv/lib/python3.8/site-packages/django/views/generic/base.py", line 84, in view
    return self.dispatch(request, *args, **kwargs)
  File "/Users/jairajsahgal/miniforge3/envs/cv/lib/python3.8/site-packages/rest_framework/views.py", line 509, in dispatch
    response = self.handle_exception(exc)
  File "/Users/jairajsahgal/miniforge3/envs/cv/lib/python3.8/site-packages/rest_framework/views.py", line 469, in handle_exception
    self.raise_uncaught_exception(exc)
  File "/Users/jairajsahgal/miniforge3/envs/cv/lib/python3.8/site-packages/rest_framework/views.py", line 480, in raise_uncaught_exception
    raise exc
  File "/Users/jairajsahgal/miniforge3/envs/cv/lib/python3.8/site-packages/rest_framework/views.py", line 506, in dispatch
    response = handler(request, *args, **kwargs)
  File "/Users/jairajsahgal/miniforge3/envs/cv/lib/python3.8/site-packages/rest_framework/decorators.py", line 50, in handler
    return func(*args, **kwargs)
  File "/Users/jairajsahgal/Documents/django/text_recognition_api/text_recognition/api/views.py", line 178, in get_text_from_image
    img = cv2.cvtColor(img, cv2.COLOR_BGR2GRAY)
cv2.error: OpenCV(4.5.3) /Users/runner/miniforge3/conda-bld/libopencv_1633800949369/work/modules/imgproc/src/color.cpp:182: error: (-215:Assertion failed) !_src.empty() in function 'cvtColor'

Internal Server Error: /account/picture-ocr/
Traceback (most recent call last):
  File "/Users/jairajsahgal/miniforge3/envs/cv/lib/python3.8/site-packages/django/core/handlers/exception.py", line 55, in inner
    response = get_response(request)
  File "/Users/jairajsahgal/miniforge3/envs/cv/lib/python3.8/site-packages/django/core/handlers/base.py", line 197, in _get_response
    response = wrapped_callback(request, *callback_args, **callback_kwargs)
  File "/Users/jairajsahgal/miniforge3/envs/cv/lib/python3.8/site-packages/django/views/decorators/csrf.py", line 54, in wrapped_view
    return view_func(*args, **kwargs)
  File "/Users/jairajsahgal/miniforge3/envs/cv/lib/python3.8/site-packages/django/views/generic/base.py", line 84, in view
    return self.dispatch(request, *args, **kwargs)
  File "/Users/jairajsahgal/miniforge3/envs/cv/lib/python3.8/site-packages/rest_framework/views.py", line 509, in dispatch
    response = self.handle_exception(exc)
  File "/Users/jairajsahgal/miniforge3/envs/cv/lib/python3.8/site-packages/rest_framework/views.py", line 469, in handle_exception
    self.raise_uncaught_exception(exc)
  File "/Users/jairajsahgal/miniforge3/envs/cv/lib/python3.8/site-packages/rest_framework/views.py", line 480, in raise_uncaught_exception
    raise exc
  File "/Users/jairajsahgal/miniforge3/envs/cv/lib/python3.8/site-packages/rest_framework/views.py", line 506, in dispatch
    response = handler(request, *args, **kwargs)
  File "/Users/jairajsahgal/miniforge3/envs/cv/lib/python3.8/site-packages/rest_framework/decorators.py", line 50, in handler
    return func(*args, **kwargs)
  File "/Users/jairajsahgal/Documents/django/text_recognition_api/text_recognition/api/views.py", line 178, in get_text_from_image
    img = cv2.cvtColor(img, cv2.COLOR_BGR2GRAY)
cv2.error: OpenCV(4.5.3) /Users/runner/miniforge3/conda-bld/libopencv_1633800949369/work/modules/imgproc/src/color.cpp:182: error: (-215:Assertion failed) !_src.empty() in function 'cvtColor'

Internal Server Error: /account/picture-ocr/
Traceback (most recent call last):
  File "/Users/jairajsahgal/miniforge3/envs/cv/lib/python3.8/site-packages/django/core/handlers/exception.py", line 55, in inner
    response = get_response(request)
  File "/Users/jairajsahgal/miniforge3/envs/cv/lib/python3.8/site-packages/django/core/handlers/base.py", line 197, in _get_response
    response = wrapped_callback(request, *callback_args, **callback_kwargs)
  File "/Users/jairajsahgal/miniforge3/envs/cv/lib/python3.8/site-packages/django/views/decorators/csrf.py", line 54, in wrapped_view
    return view_func(*args, **kwargs)
  File "/Users/jairajsahgal/miniforge3/envs/cv/lib/python3.8/site-packages/django/views/generic/base.py", line 84, in view
    return self.dispatch(request, *args, **kwargs)
  File "/Users/jairajsahgal/miniforge3/envs/cv/lib/python3.8/site-packages/rest_framework/views.py", line 509, in dispatch
    response = self.handle_exception(exc)
  File "/Users/jairajsahgal/miniforge3/envs/cv/lib/python3.8/site-packages/rest_framework/views.py", line 469, in handle_exception
    self.raise_uncaught_exception(exc)
  File "/Users/jairajsahgal/miniforge3/envs/cv/lib/python3.8/site-packages/rest_framework/views.py", line 480, in raise_uncaught_exception
    raise exc
  File "/Users/jairajsahgal/miniforge3/envs/cv/lib/python3.8/site-packages/rest_framework/views.py", line 506, in dispatch
    response = handler(request, *args, **kwargs)
  File "/Users/jairajsahgal/miniforge3/envs/cv/lib/python3.8/site-packages/rest_framework/decorators.py", line 50, in handler
    return func(*args, **kwargs)
  File "/Users/jairajsahgal/Documents/django/text_recognition_api/text_recognition/api/views.py", line 179, in get_text_from_image
    img = cv2.cvtColor(img, cv2.COLOR_BGR2GRAY)
cv2.error: OpenCV(4.5.3) /Users/runner/miniforge3/conda-bld/libopencv_1633800949369/work/modules/imgproc/src/color.cpp:182: error: (-215:Assertion failed) !_src.empty() in function 'cvtColor'

Internal Server Error: /account/picture-ocr/
Traceback (most recent call last):
  File "/Users/jairajsahgal/miniforge3/envs/cv/lib/python3.8/site-packages/django/core/handlers/exception.py", line 55, in inner
    response = get_response(request)
  File "/Users/jairajsahgal/miniforge3/envs/cv/lib/python3.8/site-packages/django/core/handlers/base.py", line 197, in _get_response
    response = wrapped_callback(request, *callback_args, **callback_kwargs)
  File "/Users/jairajsahgal/miniforge3/envs/cv/lib/python3.8/site-packages/django/views/decorators/csrf.py", line 54, in wrapped_view
    return view_func(*args, **kwargs)
  File "/Users/jairajsahgal/miniforge3/envs/cv/lib/python3.8/site-packages/django/views/generic/base.py", line 84, in view
    return self.dispatch(request, *args, **kwargs)
  File "/Users/jairajsahgal/miniforge3/envs/cv/lib/python3.8/site-packages/rest_framework/views.py", line 509, in dispatch
    response = self.handle_exception(exc)
  File "/Users/jairajsahgal/miniforge3/envs/cv/lib/python3.8/site-packages/rest_framework/views.py", line 469, in handle_exception
    self.raise_uncaught_exception(exc)
  File "/Users/jairajsahgal/miniforge3/envs/cv/lib/python3.8/site-packages/rest_framework/views.py", line 480, in raise_uncaught_exception
    raise exc
  File "/Users/jairajsahgal/miniforge3/envs/cv/lib/python3.8/site-packages/rest_framework/views.py", line 506, in dispatch
    response = handler(request, *args, **kwargs)
  File "/Users/jairajsahgal/miniforge3/envs/cv/lib/python3.8/site-packages/rest_framework/decorators.py", line 50, in handler
    return func(*args, **kwargs)
  File "/Users/jairajsahgal/Documents/django/text_recognition_api/text_recognition/api/views.py", line 179, in get_text_from_image
    img = cv2.cvtColor(img, cv2.COLOR_BGR2GRAY)
cv2.error: OpenCV(4.5.3) /Users/runner/miniforge3/conda-bld/libopencv_1633800949369/work/modules/imgproc/src/color.cpp:182: error: (-215:Assertion failed) !_src.empty() in function 'cvtColor'

Internal Server Error: /account/picture-ocr/
Traceback (most recent call last):
  File "/Users/jairajsahgal/miniforge3/envs/cv/lib/python3.8/site-packages/django/core/handlers/exception.py", line 55, in inner
    response = get_response(request)
  File "/Users/jairajsahgal/miniforge3/envs/cv/lib/python3.8/site-packages/django/core/handlers/base.py", line 197, in _get_response
    response = wrapped_callback(request, *callback_args, **callback_kwargs)
  File "/Users/jairajsahgal/miniforge3/envs/cv/lib/python3.8/site-packages/django/views/decorators/csrf.py", line 54, in wrapped_view
    return view_func(*args, **kwargs)
  File "/Users/jairajsahgal/miniforge3/envs/cv/lib/python3.8/site-packages/django/views/generic/base.py", line 84, in view
    return self.dispatch(request, *args, **kwargs)
  File "/Users/jairajsahgal/miniforge3/envs/cv/lib/python3.8/site-packages/rest_framework/views.py", line 509, in dispatch
    response = self.handle_exception(exc)
  File "/Users/jairajsahgal/miniforge3/envs/cv/lib/python3.8/site-packages/rest_framework/views.py", line 469, in handle_exception
    self.raise_uncaught_exception(exc)
  File "/Users/jairajsahgal/miniforge3/envs/cv/lib/python3.8/site-packages/rest_framework/views.py", line 480, in raise_uncaught_exception
    raise exc
  File "/Users/jairajsahgal/miniforge3/envs/cv/lib/python3.8/site-packages/rest_framework/views.py", line 506, in dispatch
    response = handler(request, *args, **kwargs)
  File "/Users/jairajsahgal/miniforge3/envs/cv/lib/python3.8/site-packages/rest_framework/decorators.py", line 50, in handler
    return func(*args, **kwargs)
  File "/Users/jairajsahgal/Documents/django/text_recognition_api/text_recognition/api/views.py", line 180, in get_text_from_image
    img = cv2.cvtColor(img, cv2.COLOR_BGR2GRAY)
cv2.error: OpenCV(4.5.3) /Users/runner/miniforge3/conda-bld/libopencv_1633800949369/work/modules/imgproc/src/color.cpp:182: error: (-215:Assertion failed) !_src.empty() in function 'cvtColor'

Internal Server Error: /account/picture-ocr/
Traceback (most recent call last):
  File "/Users/jairajsahgal/miniforge3/envs/cv/lib/python3.8/site-packages/django/core/handlers/exception.py", line 55, in inner
    response = get_response(request)
  File "/Users/jairajsahgal/miniforge3/envs/cv/lib/python3.8/site-packages/django/core/handlers/base.py", line 197, in _get_response
    response = wrapped_callback(request, *callback_args, **callback_kwargs)
  File "/Users/jairajsahgal/miniforge3/envs/cv/lib/python3.8/site-packages/django/views/decorators/csrf.py", line 54, in wrapped_view
    return view_func(*args, **kwargs)
  File "/Users/jairajsahgal/miniforge3/envs/cv/lib/python3.8/site-packages/django/views/generic/base.py", line 84, in view
    return self.dispatch(request, *args, **kwargs)
  File "/Users/jairajsahgal/miniforge3/envs/cv/lib/python3.8/site-packages/rest_framework/views.py", line 509, in dispatch
    response = self.handle_exception(exc)
  File "/Users/jairajsahgal/miniforge3/envs/cv/lib/python3.8/site-packages/rest_framework/views.py", line 469, in handle_exception
    self.raise_uncaught_exception(exc)
  File "/Users/jairajsahgal/miniforge3/envs/cv/lib/python3.8/site-packages/rest_framework/views.py", line 480, in raise_uncaught_exception
    raise exc
  File "/Users/jairajsahgal/miniforge3/envs/cv/lib/python3.8/site-packages/rest_framework/views.py", line 506, in dispatch
    response = handler(request, *args, **kwargs)
  File "/Users/jairajsahgal/miniforge3/envs/cv/lib/python3.8/site-packages/rest_framework/decorators.py", line 50, in handler
    return func(*args, **kwargs)
  File "/Users/jairajsahgal/Documents/django/text_recognition_api/text_recognition/api/views.py", line 180, in get_text_from_image
    img = cv2.cvtColor(img, cv2.COLOR_BGR2GRAY)
cv2.error: OpenCV(4.5.3) /Users/runner/miniforge3/conda-bld/libopencv_1633800949369/work/modules/imgproc/src/color.cpp:182: error: (-215:Assertion failed) !_src.empty() in function 'cvtColor'

Internal Server Error: /account/picture-ocr/
Traceback (most recent call last):
  File "/Users/jairajsahgal/miniforge3/envs/cv/lib/python3.8/site-packages/django/core/handlers/exception.py", line 55, in inner
    response = get_response(request)
  File "/Users/jairajsahgal/miniforge3/envs/cv/lib/python3.8/site-packages/django/core/handlers/base.py", line 197, in _get_response
    response = wrapped_callback(request, *callback_args, **callback_kwargs)
  File "/Users/jairajsahgal/miniforge3/envs/cv/lib/python3.8/site-packages/django/views/decorators/csrf.py", line 54, in wrapped_view
    return view_func(*args, **kwargs)
  File "/Users/jairajsahgal/miniforge3/envs/cv/lib/python3.8/site-packages/django/views/generic/base.py", line 84, in view
    return self.dispatch(request, *args, **kwargs)
  File "/Users/jairajsahgal/miniforge3/envs/cv/lib/python3.8/site-packages/rest_framework/views.py", line 509, in dispatch
    response = self.handle_exception(exc)
  File "/Users/jairajsahgal/miniforge3/envs/cv/lib/python3.8/site-packages/rest_framework/views.py", line 469, in handle_exception
    self.raise_uncaught_exception(exc)
  File "/Users/jairajsahgal/miniforge3/envs/cv/lib/python3.8/site-packages/rest_framework/views.py", line 480, in raise_uncaught_exception
    raise exc
  File "/Users/jairajsahgal/miniforge3/envs/cv/lib/python3.8/site-packages/rest_framework/views.py", line 506, in dispatch
    response = handler(request, *args, **kwargs)
  File "/Users/jairajsahgal/miniforge3/envs/cv/lib/python3.8/site-packages/rest_framework/decorators.py", line 50, in handler
    return func(*args, **kwargs)
  File "/Users/jairajsahgal/Documents/django/text_recognition_api/text_recognition/api/views.py", line 177, in get_text_from_image
    img = cv2.cvtColor(img, cv2.COLOR_BGR2GRAY)
cv2.error: OpenCV(4.5.3) /Users/runner/miniforge3/conda-bld/libopencv_1633800949369/work/modules/imgproc/src/color.cpp:182: error: (-215:Assertion failed) !_src.empty() in function 'cvtColor'

Internal Server Error: /account/picture-ocr/
Traceback (most recent call last):
  File "/Users/jairajsahgal/miniforge3/envs/cv/lib/python3.8/site-packages/django/core/handlers/exception.py", line 55, in inner
    response = get_response(request)
  File "/Users/jairajsahgal/miniforge3/envs/cv/lib/python3.8/site-packages/django/core/handlers/base.py", line 197, in _get_response
    response = wrapped_callback(request, *callback_args, **callback_kwargs)
  File "/Users/jairajsahgal/miniforge3/envs/cv/lib/python3.8/site-packages/django/views/decorators/csrf.py", line 54, in wrapped_view
    return view_func(*args, **kwargs)
  File "/Users/jairajsahgal/miniforge3/envs/cv/lib/python3.8/site-packages/django/views/generic/base.py", line 84, in view
    return self.dispatch(request, *args, **kwargs)
  File "/Users/jairajsahgal/miniforge3/envs/cv/lib/python3.8/site-packages/rest_framework/views.py", line 509, in dispatch
    response = self.handle_exception(exc)
  File "/Users/jairajsahgal/miniforge3/envs/cv/lib/python3.8/site-packages/rest_framework/views.py", line 469, in handle_exception
    self.raise_uncaught_exception(exc)
  File "/Users/jairajsahgal/miniforge3/envs/cv/lib/python3.8/site-packages/rest_framework/views.py", line 480, in raise_uncaught_exception
    raise exc
  File "/Users/jairajsahgal/miniforge3/envs/cv/lib/python3.8/site-packages/rest_framework/views.py", line 506, in dispatch
    response = handler(request, *args, **kwargs)
  File "/Users/jairajsahgal/miniforge3/envs/cv/lib/python3.8/site-packages/rest_framework/decorators.py", line 50, in handler
    return func(*args, **kwargs)
  File "/Users/jairajsahgal/Documents/django/text_recognition_api/text_recognition/api/views.py", line 173, in get_text_from_image
    logger.info(type(Image.open(pictureObject.image)))
NameError: name 'Image' is not defined
Internal Server Error: /account/picture-ocr/
Traceback (most recent call last):
  File "/Users/jairajsahgal/miniforge3/envs/cv/lib/python3.8/site-packages/django/core/handlers/exception.py", line 55, in inner
    response = get_response(request)
  File "/Users/jairajsahgal/miniforge3/envs/cv/lib/python3.8/site-packages/django/core/handlers/base.py", line 197, in _get_response
    response = wrapped_callback(request, *callback_args, **callback_kwargs)
  File "/Users/jairajsahgal/miniforge3/envs/cv/lib/python3.8/site-packages/django/views/decorators/csrf.py", line 54, in wrapped_view
    return view_func(*args, **kwargs)
  File "/Users/jairajsahgal/miniforge3/envs/cv/lib/python3.8/site-packages/django/views/generic/base.py", line 84, in view
    return self.dispatch(request, *args, **kwargs)
  File "/Users/jairajsahgal/miniforge3/envs/cv/lib/python3.8/site-packages/rest_framework/views.py", line 509, in dispatch
    response = self.handle_exception(exc)
  File "/Users/jairajsahgal/miniforge3/envs/cv/lib/python3.8/site-packages/rest_framework/views.py", line 469, in handle_exception
    self.raise_uncaught_exception(exc)
  File "/Users/jairajsahgal/miniforge3/envs/cv/lib/python3.8/site-packages/rest_framework/views.py", line 480, in raise_uncaught_exception
    raise exc
  File "/Users/jairajsahgal/miniforge3/envs/cv/lib/python3.8/site-packages/rest_framework/views.py", line 506, in dispatch
    response = handler(request, *args, **kwargs)
  File "/Users/jairajsahgal/miniforge3/envs/cv/lib/python3.8/site-packages/rest_framework/decorators.py", line 50, in handler
    return func(*args, **kwargs)
  File "/Users/jairajsahgal/Documents/django/text_recognition_api/text_recognition/api/views.py", line 177, in get_text_from_image
    img = cv2.cvtColor(img, cv2.COLOR_BGR2GRAY)
cv2.error: OpenCV(4.5.3) /Users/runner/miniforge3/conda-bld/libopencv_1633800949369/work/modules/imgproc/src/color.cpp:182: error: (-215:Assertion failed) !_src.empty() in function 'cvtColor'

Internal Server Error: /account/picture-ocr/
Traceback (most recent call last):
  File "/Users/jairajsahgal/miniforge3/envs/cv/lib/python3.8/site-packages/django/core/handlers/exception.py", line 55, in inner
    response = get_response(request)
  File "/Users/jairajsahgal/miniforge3/envs/cv/lib/python3.8/site-packages/django/core/handlers/base.py", line 197, in _get_response
    response = wrapped_callback(request, *callback_args, **callback_kwargs)
  File "/Users/jairajsahgal/miniforge3/envs/cv/lib/python3.8/site-packages/django/views/decorators/csrf.py", line 54, in wrapped_view
    return view_func(*args, **kwargs)
  File "/Users/jairajsahgal/miniforge3/envs/cv/lib/python3.8/site-packages/django/views/generic/base.py", line 84, in view
    return self.dispatch(request, *args, **kwargs)
  File "/Users/jairajsahgal/miniforge3/envs/cv/lib/python3.8/site-packages/rest_framework/views.py", line 509, in dispatch
    response = self.handle_exception(exc)
  File "/Users/jairajsahgal/miniforge3/envs/cv/lib/python3.8/site-packages/rest_framework/views.py", line 469, in handle_exception
    self.raise_uncaught_exception(exc)
  File "/Users/jairajsahgal/miniforge3/envs/cv/lib/python3.8/site-packages/rest_framework/views.py", line 480, in raise_uncaught_exception
    raise exc
  File "/Users/jairajsahgal/miniforge3/envs/cv/lib/python3.8/site-packages/rest_framework/views.py", line 506, in dispatch
    response = handler(request, *args, **kwargs)
  File "/Users/jairajsahgal/miniforge3/envs/cv/lib/python3.8/site-packages/rest_framework/decorators.py", line 50, in handler
    return func(*args, **kwargs)
  File "/Users/jairajsahgal/Documents/django/text_recognition_api/text_recognition/api/views.py", line 178, in get_text_from_image
    img = cv2.cvtColor(img, cv2.COLOR_BGR2GRAY)
cv2.error: OpenCV(4.5.3) /Users/runner/miniforge3/conda-bld/libopencv_1633800949369/work/modules/imgproc/src/color.cpp:182: error: (-215:Assertion failed) !_src.empty() in function 'cvtColor'

Internal Server Error: /account/picture-ocr/
Traceback (most recent call last):
  File "/Users/jairajsahgal/miniforge3/envs/cv/lib/python3.8/site-packages/django/core/handlers/exception.py", line 55, in inner
    response = get_response(request)
  File "/Users/jairajsahgal/miniforge3/envs/cv/lib/python3.8/site-packages/django/core/handlers/base.py", line 197, in _get_response
    response = wrapped_callback(request, *callback_args, **callback_kwargs)
  File "/Users/jairajsahgal/miniforge3/envs/cv/lib/python3.8/site-packages/django/views/decorators/csrf.py", line 54, in wrapped_view
    return view_func(*args, **kwargs)
  File "/Users/jairajsahgal/miniforge3/envs/cv/lib/python3.8/site-packages/django/views/generic/base.py", line 84, in view
    return self.dispatch(request, *args, **kwargs)
  File "/Users/jairajsahgal/miniforge3/envs/cv/lib/python3.8/site-packages/rest_framework/views.py", line 509, in dispatch
    response = self.handle_exception(exc)
  File "/Users/jairajsahgal/miniforge3/envs/cv/lib/python3.8/site-packages/rest_framework/views.py", line 469, in handle_exception
    self.raise_uncaught_exception(exc)
  File "/Users/jairajsahgal/miniforge3/envs/cv/lib/python3.8/site-packages/rest_framework/views.py", line 480, in raise_uncaught_exception
    raise exc
  File "/Users/jairajsahgal/miniforge3/envs/cv/lib/python3.8/site-packages/rest_framework/views.py", line 506, in dispatch
    response = handler(request, *args, **kwargs)
  File "/Users/jairajsahgal/miniforge3/envs/cv/lib/python3.8/site-packages/rest_framework/decorators.py", line 50, in handler
    return func(*args, **kwargs)
  File "/Users/jairajsahgal/Documents/django/text_recognition_api/text_recognition/api/views.py", line 174, in get_text_from_image
    img = Image.open('Image.jpg').convert('RGB')
  File "/Users/jairajsahgal/miniforge3/envs/cv/lib/python3.8/site-packages/PIL/Image.py", line 3068, in open
    fp = builtins.open(filename, "rb")
FileNotFoundError: [Errno 2] No such file or directory: 'Image.jpg'
Unauthorized: /account/picture-ocr/
Unauthorized: /account/picture-ocr/
Unauthorized: /account/picture-list/
